Workbook

Sheet Summary
A1: Metric | B1: S1 | C1: S2 | D1: S3 | E1: S3s | F1: S4 | G1: S5 | H1: S6 | I1: S6s
A2: Scenario | B2: =VLOOKUP(B$1,Runs!$A$2:$B$9,2,FALSE()) -> 1 | C2: =VLOOKUP(C$1,Runs!$A$2:$B$9,2,FALSE()) -> 2 | D2: =VLOOKUP(D$1,Runs!$A$2:$B$9,2,FALSE()) -> 3 | E2: =VLOOKUP(E$1,Runs!$A$2:$B$9,2,FALSE()) -> 3 | F2: =VLOOKUP(F$1,Runs!$A$2:$B$9,2,FALSE()) -> 4 | G2: =VLOOKUP(G$1,Runs!$A$2:$B$9,2,FALSE()) -> 5 | H2: =VLOOKUP(H$1,Runs!$A$2:$B$9,2,FALSE()) -> 6 | I2: =VLOOKUP(I$1,Runs!$A$2:$B$9,2,FALSE()) -> 6
A3: Sim. avg lead time (min) | B3: =Final_Values!B12 -> 855.34074 | C3: =Final_Values!C12 -> 1527.9048 | D3: =Final_Values!D12 -> 1143.24 | E3: =Final_Values!E12 -> 1482.7733 | F3: =Final_Values!F12 -> 1623.3733 | G3: =Final_Values!G12 -> 1091.4533 | H3: =Final_Values!H12 -> 1112.8667 | I3: =Final_Values!I12 -> 1070.6619
A4: Real avg lead time (s) | B4: =Final_Values!B13 -> 857.66667 | C4: =Final_Values!C13 -> 1482 | D4: =Final_Values!D13 -> 1588.4 | E4: =Final_Values!E13 -> 1588.4 | F4: =Final_Values!F13 -> 1552 | G4: =Final_Values!G13 -> 981.1 | H4: =Final_Values!H13 -> 997.66667 | I4: =Final_Values!I13 -> 1054.5714
A5: Lead time deviation | B5: =Final_Values!B14 -> -0.002711923 | C5: =Final_Values!C14 -> 0.030974873 | D5: =Final_Values!D14 -> -0.28025686 | E5: =Final_Values!E14 -> -0.066498783 | F5: =Final_Values!F14 -> 0.045987972 | G5: =Final_Values!G14 -> 0.11247919 | H5: =Final_Values!H14 -> 0.11546943 | I5: =Final_Values!I14 -> 0.015257834
A6: Sim. avg utilization | B6: =Final_Values!B17 -> 0.57810199 | C6: =Final_Values!C17 -> 0.94038141 | D6: =Final_Values!D17 -> 0.64461025 | E6: =Final_Values!E17 -> 0.6206336 | F6: =Final_Values!F17 -> 0.78390163 | G6: =Final_Values!G17 -> 0.65787411 | H6: =Final_Values!H17 -> 0.47584827 | I6: =Final_Values!I17 -> 0.51237182
A7: Real avg utilization | B7: =Final_Values!B18 -> 0.55656733 | C7: =Final_Values!C18 -> 0.90500828 | D7: =Final_Values!D18 -> 0.60310013 | E7: =Final_Values!E18 -> 0.60310013 | F7: =Final_Values!F18 -> 0.70808614 | G7: =Final_Values!G18 -> 0.69496738 | H7: =Final_Values!H18 -> 0.5332778 | I7: =Final_Values!I18 -> 0.5332778
A8: Utilization deviation (pp) | B8: =Final_Values!B19 -> 2.1534658 | C8: =Final_Values!C19 -> 3.5373131 | D8: =Final_Values!D19 -> 4.1510129 | E8: =Final_Values!E19 -> 1.7533472 | F8: =Final_Values!F19 -> 7.5815482 | G8: =Final_Values!G19 -> -3.7093267 | H8: =Final_Values!H19 -> -5.7429531 | I8: =Final_Values!I19 -> -2.0905979
A9: Sim. components | B9: =Final_Values!B21 -> 69 | C9: =Final_Values!C21 -> 106 | D9: =Final_Values!D21 -> 118 | E9: =Final_Values!E21 -> 97 | F9: =Final_Values!F21 -> 100 | G9: =Final_Values!G21 -> 107 | H9: =Final_Values!H21 -> 76 | I9: =Final_Values!I21 -> 85
A10: Real components | B10: =Final_Values!B22 -> 72 | C10: =Final_Values!C22 -> 110 | D10: =Final_Values!D22 -> 118 | E10: =Final_Values!E22 -> 118 | F10: =Final_Values!F22 -> 103 | G10: =Final_Values!G22 -> 107 | H10: =Final_Values!H22 -> 87 | I10: =Final_Values!I22 -> 87
A11: Component count deviation | B11: =Final_Values!B23 -> -0.041666667 | C11: =Final_Values!C23 -> -0.036363636 | D11: =Final_Values!D23 -> 0 | E11: =Final_Values!E23 -> -0.1779661 | F11: =Final_Values!F23 -> -0.029126214 | G11: =Final_Values!G23 -> 0 | H11: =Final_Values!H23 -> -0.12643678 | I11: =Final_Values!I23 -> -0.022988506
A12: Sim. remaining parts | B12: =Final_Values!B24 -> 9 | C12: =Final_Values!C24 -> 7 | D12: =Final_Values!D24 -> 7 | E12: =Final_Values!E24 -> 5 | F12: =Final_Values!F24 -> 5 | G12: =Final_Values!G24 -> 10 | H12: =Final_Values!H24 -> 6 | I12: =Final_Values!I24 -> 8
A13: Real remaining parts | B13: =Final_Values!B25 -> 10 | C13: =Final_Values!C25 -> 8 | D13: =Final_Values!D25 -> 5 | E13: =Final_Values!E25 -> 5 | F13: =Final_Values!F25 -> 6 | G13: =Final_Values!G25 -> 10 | H13: =Final_Values!H25 -> 10 | I13: =Final_Values!I25 -> 10
A14: Remaining parts deviation | B14: =Final_Values!B26 -> -0.1 | C14: =Final_Values!C26 -> -0.125 | D14: =Final_Values!D26 -> 0.4 | E14: =Final_Values!E26 -> 0 | F14: =Final_Values!F26 -> -0.16666667 | G14: =Final_Values!G26 -> 0 | H14: =Final_Values!H26 -> -0.4 | I14: =Final_Values!I26 -> -0.2
A15: Assessment (±20 %) | B15: =Final_Values!B28 -> Pass | C15: =Final_Values!C28 -> Pass | D15: =Final_Values!D28 -> Fail | E15: =Final_Values!E28 -> Pass | F15: =Final_Values!F28 -> Pass | G15: =Final_Values!G28 -> Pass | H15: =Final_Values!H28 -> Pass | I15: =Final_Values!I28 -> Pass

Sheet Final_Values
A1: Metric | B1: S1 | C1: S2 | D1: S3 | E1: S3s | F1: S4 | G1: S5 | H1: S6 | I1: S6s | J1: Unit
A2: Scenario | B2: =VLOOKUP(B$1,Runs!$A$2:$B$9,2,FALSE()) -> 1 | C2: =VLOOKUP(C$1,Runs!$A$2:$B$9,2,FALSE()) -> 2 | D2: =VLOOKUP(D$1,Runs!$A$2:$B$9,2,FALSE()) -> 3 | E2: =VLOOKUP(E$1,Runs!$A$2:$B$9,2,FALSE()) -> 3 | F2: =VLOOKUP(F$1,Runs!$A$2:$B$9,2,FALSE()) -> 4 | G2: =VLOOKUP(G$1,Runs!$A$2:$B$9,2,FALSE()) -> 5 | H2: =VLOOKUP(H$1,Runs!$A$2:$B$9,2,FALSE()) -> 6 | I2: =VLOOKUP(I$1,Runs!$A$2:$B$9,2,FALSE()) -> 6
A3: Experiment | B3: =VLOOKUP(B$1,Runs!$A$2:$C$9,3,FALSE()) -> exp12_scenario_01 | C3: =VLOOKUP(C$1,Runs!$A$2:$C$9,3,FALSE()) -> exp13_scenario_02 | D3: =VLOOKUP(D$1,Runs!$A$2:$C$9,3,FALSE()) -> exp14_scenario_03 | E3: =VLOOKUP(E$1,Runs!$A$2:$C$9,3,FALSE()) -> exp14_scenario_03_sensitivity | F3: =VLOOKUP(F$1,Runs!$A$2:$C$9,3,FALSE()) -> exp15_scenario_04 | G3: =VLOOKUP(G$1,Runs!$A$2:$C$9,3,FALSE()) -> exp16_scenario_05 | H3: =VLOOKUP(H$1,Runs!$A$2:$C$9,3,FALSE()) -> exp17_scenario_06 | I3: =VLOOKUP(I$1,Runs!$A$2:$C$9,3,FALSE()) -> exp17_scenario_06_sensitivity
A4: LEAD TIME
A5: POs in average (complete in sim and factory) | B5: =COUNTIFS(Calc_LeadTime!$A$2:$A$81,B$1,Calc_LeadTime!$Y$2:$Y$81,1) -> 9 | C5: =COUNTIFS(Calc_LeadTime!$A$2:$A$81,C$1,Calc_LeadTime!$Y$2:$Y$81,1) -> 7 | D5: =COUNTIFS(Calc_LeadTime!$A$2:$A$81,D$1,Calc_LeadTime!$Y$2:$Y$81,1) -> 5 | E5: =COUNTIFS(Calc_LeadTime!$A$2:$A$81,E$1,Calc_LeadTime!$Y$2:$Y$81,1) -> 5 | F5: =COUNTIFS(Calc_LeadTime!$A$2:$A$81,F$1,Calc_LeadTime!$Y$2:$Y$81,1) -> 5 | G5: =COUNTIFS(Calc_LeadTime!$A$2:$A$81,G$1,Calc_LeadTime!$Y$2:$Y$81,1) -> 10 | H5: =COUNTIFS(Calc_LeadTime!$A$2:$A$81,H$1,Calc_LeadTime!$Y$2:$Y$81,1) -> 6 | I5: =COUNTIFS(Calc_LeadTime!$A$2:$A$81,I$1,Calc_LeadTime!$Y$2:$Y$81,1) -> 7 | J5: POs
A6: POs excluded: DNF (sim) | B6: =COUNTIFS(Calc_LeadTime!$A$2:$A$81,B$1,Calc_LeadTime!$X$2:$X$81,"DNF (sim)") -> 1 | C6: =COUNTIFS(Calc_LeadTime!$A$2:$A$81,C$1,Calc_LeadTime!$X$2:$X$81,"DNF (sim)") -> 1 | D6: =COUNTIFS(Calc_LeadTime!$A$2:$A$81,D$1,Calc_LeadTime!$X$2:$X$81,"DNF (sim)") -> 0 | E6: =COUNTIFS(Calc_LeadTime!$A$2:$A$81,E$1,Calc_LeadTime!$X$2:$X$81,"DNF (sim)") -> 0 | F6: =COUNTIFS(Calc_LeadTime!$A$2:$A$81,F$1,Calc_LeadTime!$X$2:$X$81,"DNF (sim)") -> 1 | G6: =COUNTIFS(Calc_LeadTime!$A$2:$A$81,G$1,Calc_LeadTime!$X$2:$X$81,"DNF (sim)") -> 0 | H6: =COUNTIFS(Calc_LeadTime!$A$2:$A$81,H$1,Calc_LeadTime!$X$2:$X$81,"DNF (sim)") -> 2 | I6: =COUNTIFS(Calc_LeadTime!$A$2:$A$81,I$1,Calc_LeadTime!$X$2:$X$81,"DNF (sim)") -> 1 | J6: POs
A7: POs excluded: DNF (factory) | B7: =COUNTIFS(Calc_LeadTime!$A$2:$A$81,B$1,Calc_LeadTime!$X$2:$X$81,"DNF (factory)") -> 0 | C7: =COUNTIFS(Calc_LeadTime!$A$2:$A$81,C$1,Calc_LeadTime!$X$2:$X$81,"DNF (factory)") -> 0 | D7: =COUNTIFS(Calc_LeadTime!$A$2:$A$81,D$1,Calc_LeadTime!$X$2:$X$81,"DNF (factory)") -> 2 | E7: =COUNTIFS(Calc_LeadTime!$A$2:$A$81,E$1,Calc_LeadTime!$X$2:$X$81,"DNF (factory)") -> 0 | F7: =COUNTIFS(Calc_LeadTime!$A$2:$A$81,F$1,Calc_LeadTime!$X$2:$X$81,"DNF (factory)") -> 0 | G7: =COUNTIFS(Calc_LeadTime!$A$2:$A$81,G$1,Calc_LeadTime!$X$2:$X$81,"DNF (factory)") -> 0 | H7: =COUNTIFS(Calc_LeadTime!$A$2:$A$81,H$1,Calc_LeadTime!$X$2:$X$81,"DNF (factory)") -> 0 | I7: =COUNTIFS(Calc_LeadTime!$A$2:$A$81,I$1,Calc_LeadTime!$X$2:$X$81,"DNF (factory)") -> 1 | J7: POs
A8: POs excluded: DNF (sim + factory) | B8: =COUNTIFS(Calc_LeadTime!$A$2:$A$81,B$1,Calc_LeadTime!$X$2:$X$81,"DNF (sim + factory)") -> 0 | C8: =COUNTIFS(Calc_LeadTime!$A$2:$A$81,C$1,Calc_LeadTime!$X$2:$X$81,"DNF (sim + factory)") -> 2 | D8: =COUNTIFS(Calc_LeadTime!$A$2:$A$81,D$1,Calc_LeadTime!$X$2:$X$81,"DNF (sim + factory)") -> 3 | E8: =COUNTIFS(Calc_LeadTime!$A$2:$A$81,E$1,Calc_LeadTime!$X$2:$X$81,"DNF (sim + factory)") -> 5 | F8: =COUNTIFS(Calc_LeadTime!$A$2:$A$81,F$1,Calc_LeadTime!$X$2:$X$81,"DNF (sim + factory)") -> 4 | G8: =COUNTIFS(Calc_LeadTime!$A$2:$A$81,G$1,Calc_LeadTime!$X$2:$X$81,"DNF (sim + factory)") -> 0 | H8: =COUNTIFS(Calc_LeadTime!$A$2:$A$81,H$1,Calc_LeadTime!$X$2:$X$81,"DNF (sim + factory)") -> 2 | I8: =COUNTIFS(Calc_LeadTime!$A$2:$A$81,I$1,Calc_LeadTime!$X$2:$X$81,"DNF (sim + factory)") -> 1 | J8: POs
A9: Sim. avg VT | B9: =AVERAGEIFS(Calc_LeadTime!$J$2:$J$81,Calc_LeadTime!$A$2:$A$81,B$1,Calc_LeadTime!$Y$2:$Y$81,1) -> 429.21111 | C9: =AVERAGEIFS(Calc_LeadTime!$J$2:$J$81,Calc_LeadTime!$A$2:$A$81,C$1,Calc_LeadTime!$Y$2:$Y$81,1) -> 1089.3 | D9: =AVERAGEIFS(Calc_LeadTime!$J$2:$J$81,Calc_LeadTime!$A$2:$A$81,D$1,Calc_LeadTime!$Y$2:$Y$81,1) -> 798.7 | E9: =AVERAGEIFS(Calc_LeadTime!$J$2:$J$81,Calc_LeadTime!$A$2:$A$81,E$1,Calc_LeadTime!$Y$2:$Y$81,1) -> 1027.3 | F9: =AVERAGEIFS(Calc_LeadTime!$J$2:$J$81,Calc_LeadTime!$A$2:$A$81,F$1,Calc_LeadTime!$Y$2:$Y$81,1) -> 1211.3 | G9: =AVERAGEIFS(Calc_LeadTime!$J$2:$J$81,Calc_LeadTime!$A$2:$A$81,G$1,Calc_LeadTime!$Y$2:$Y$81,1) -> 788.92 | H9: =AVERAGEIFS(Calc_LeadTime!$J$2:$J$81,Calc_LeadTime!$A$2:$A$81,H$1,Calc_LeadTime!$Y$2:$Y$81,1) -> 612.3 | I9: =AVERAGEIFS(Calc_LeadTime!$J$2:$J$81,Calc_LeadTime!$A$2:$A$81,I$1,Calc_LeadTime!$Y$2:$Y$81,1) -> 604.15714 | J9: min
A10: Sim. avg NCT (workstations) | B10: =AVERAGEIFS(Calc_LeadTime!$L$2:$L$81,Calc_LeadTime!$A$2:$A$81,B$1,Calc_LeadTime!$Y$2:$Y$81,1) -> 386.46 | C10: =AVERAGEIFS(Calc_LeadTime!$L$2:$L$81,Calc_LeadTime!$A$2:$A$81,C$1,Calc_LeadTime!$Y$2:$Y$81,1) -> 400.88 | D10: =AVERAGEIFS(Calc_LeadTime!$L$2:$L$81,Calc_LeadTime!$A$2:$A$81,D$1,Calc_LeadTime!$Y$2:$Y$81,1) -> 323.724 | E10: =AVERAGEIFS(Calc_LeadTime!$L$2:$L$81,Calc_LeadTime!$A$2:$A$81,E$1,Calc_LeadTime!$Y$2:$Y$81,1) -> 548.652 | F10: =AVERAGEIFS(Calc_LeadTime!$L$2:$L$81,Calc_LeadTime!$A$2:$A$81,F$1,Calc_LeadTime!$Y$2:$Y$81,1) -> 343.312 | G10: =AVERAGEIFS(Calc_LeadTime!$L$2:$L$81,Calc_LeadTime!$A$2:$A$81,G$1,Calc_LeadTime!$Y$2:$Y$81,1) -> 262.016 | H10: =AVERAGEIFS(Calc_LeadTime!$L$2:$L$81,Calc_LeadTime!$A$2:$A$81,H$1,Calc_LeadTime!$Y$2:$Y$81,1) -> 485.885 | I10: =AVERAGEIFS(Calc_LeadTime!$L$2:$L$81,Calc_LeadTime!$A$2:$A$81,I$1,Calc_LeadTime!$Y$2:$Y$81,1) -> 454.65714 | J10: min
A11: Factory avg handling time | B11: =AVERAGEIFS(Calc_LeadTime!$S$2:$S$81,Calc_LeadTime!$A$2:$A$81,B$1,Calc_LeadTime!$Y$2:$Y$81,1) -> 442.11111 | C11: =AVERAGEIFS(Calc_LeadTime!$S$2:$S$81,Calc_LeadTime!$A$2:$A$81,C$1,Calc_LeadTime!$Y$2:$Y$81,1) -> 1121 | D11: =AVERAGEIFS(Calc_LeadTime!$S$2:$S$81,Calc_LeadTime!$A$2:$A$81,D$1,Calc_LeadTime!$Y$2:$Y$81,1) -> 766 | E11: =AVERAGEIFS(Calc_LeadTime!$S$2:$S$81,Calc_LeadTime!$A$2:$A$81,E$1,Calc_LeadTime!$Y$2:$Y$81,1) -> 766 | F11: =AVERAGEIFS(Calc_LeadTime!$S$2:$S$81,Calc_LeadTime!$A$2:$A$81,F$1,Calc_LeadTime!$Y$2:$Y$81,1) -> 1302.8 | G11: =AVERAGEIFS(Calc_LeadTime!$S$2:$S$81,Calc_LeadTime!$A$2:$A$81,G$1,Calc_LeadTime!$Y$2:$Y$81,1) -> 800.6 | H11: =AVERAGEIFS(Calc_LeadTime!$S$2:$S$81,Calc_LeadTime!$A$2:$A$81,H$1,Calc_LeadTime!$Y$2:$Y$81,1) -> 613.66667 | I11: =AVERAGEIFS(Calc_LeadTime!$S$2:$S$81,Calc_LeadTime!$A$2:$A$81,I$1,Calc_LeadTime!$Y$2:$Y$81,1) -> 653 | J11: s
A12: Sim. avg lead time | B12: =AVERAGEIFS(Calc_LeadTime!$H$2:$H$81,Calc_LeadTime!$A$2:$A$81,B$1,Calc_LeadTime!$Y$2:$Y$81,1) -> 855.34074 | C12: =AVERAGEIFS(Calc_LeadTime!$H$2:$H$81,Calc_LeadTime!$A$2:$A$81,C$1,Calc_LeadTime!$Y$2:$Y$81,1) -> 1527.9048 | D12: =AVERAGEIFS(Calc_LeadTime!$H$2:$H$81,Calc_LeadTime!$A$2:$A$81,D$1,Calc_LeadTime!$Y$2:$Y$81,1) -> 1143.24 | E12: =AVERAGEIFS(Calc_LeadTime!$H$2:$H$81,Calc_LeadTime!$A$2:$A$81,E$1,Calc_LeadTime!$Y$2:$Y$81,1) -> 1482.7733 | F12: =AVERAGEIFS(Calc_LeadTime!$H$2:$H$81,Calc_LeadTime!$A$2:$A$81,F$1,Calc_LeadTime!$Y$2:$Y$81,1) -> 1623.3733 | G12: =AVERAGEIFS(Calc_LeadTime!$H$2:$H$81,Calc_LeadTime!$A$2:$A$81,G$1,Calc_LeadTime!$Y$2:$Y$81,1) -> 1091.4533 | H12: =AVERAGEIFS(Calc_LeadTime!$H$2:$H$81,Calc_LeadTime!$A$2:$A$81,H$1,Calc_LeadTime!$Y$2:$Y$81,1) -> 1112.8667 | I12: =AVERAGEIFS(Calc_LeadTime!$H$2:$H$81,Calc_LeadTime!$A$2:$A$81,I$1,Calc_LeadTime!$Y$2:$Y$81,1) -> 1070.6619 | J12: min
A13: Real avg lead time | B13: =AVERAGEIFS(Calc_LeadTime!$U$2:$U$81,Calc_LeadTime!$A$2:$A$81,B$1,Calc_LeadTime!$Y$2:$Y$81,1) -> 857.66667 | C13: =AVERAGEIFS(Calc_LeadTime!$U$2:$U$81,Calc_LeadTime!$A$2:$A$81,C$1,Calc_LeadTime!$Y$2:$Y$81,1) -> 1482 | D13: =AVERAGEIFS(Calc_LeadTime!$U$2:$U$81,Calc_LeadTime!$A$2:$A$81,D$1,Calc_LeadTime!$Y$2:$Y$81,1) -> 1588.4 | E13: =AVERAGEIFS(Calc_LeadTime!$U$2:$U$81,Calc_LeadTime!$A$2:$A$81,E$1,Calc_LeadTime!$Y$2:$Y$81,1) -> 1588.4 | F13: =AVERAGEIFS(Calc_LeadTime!$U$2:$U$81,Calc_LeadTime!$A$2:$A$81,F$1,Calc_LeadTime!$Y$2:$Y$81,1) -> 1552 | G13: =AVERAGEIFS(Calc_LeadTime!$U$2:$U$81,Calc_LeadTime!$A$2:$A$81,G$1,Calc_LeadTime!$Y$2:$Y$81,1) -> 981.1 | H13: =AVERAGEIFS(Calc_LeadTime!$U$2:$U$81,Calc_LeadTime!$A$2:$A$81,H$1,Calc_LeadTime!$Y$2:$Y$81,1) -> 997.66667 | I13: =AVERAGEIFS(Calc_LeadTime!$U$2:$U$81,Calc_LeadTime!$A$2:$A$81,I$1,Calc_LeadTime!$Y$2:$Y$81,1) -> 1054.5714 | J13: s
A14: Lead time deviation | B14: =(B12-B13)/B13 -> -0.002711923 | C14: =(C12-C13)/C13 -> 0.030974873 | D14: =(D12-D13)/D13 -> -0.28025686 | E14: =(E12-E13)/E13 -> -0.066498783 | F14: =(F12-F13)/F13 -> 0.045987972 | G14: =(G12-G13)/G13 -> 0.11247919 | H14: =(H12-H13)/H13 -> 0.11546943 | I14: =(I12-I13)/I13 -> 0.015257834 | J14: %
A15: UTILIZATION
A16: Workstations | B16: =COUNTIFS(Calc_Stations!$A$2:$A$38,B$1) -> 3 | C16: =COUNTIFS(Calc_Stations!$A$2:$A$38,C$1) -> 4 | D16: =COUNTIFS(Calc_Stations!$A$2:$A$38,D$1) -> 5 | E16: =COUNTIFS(Calc_Stations!$A$2:$A$38,E$1) -> 5 | F16: =COUNTIFS(Calc_Stations!$A$2:$A$38,F$1) -> 5 | G16: =COUNTIFS(Calc_Stations!$A$2:$A$38,G$1) -> 5 | H16: =COUNTIFS(Calc_Stations!$A$2:$A$38,H$1) -> 5 | I16: =COUNTIFS(Calc_Stations!$A$2:$A$38,I$1) -> 5 | J16: stations
A17: Sim. avg utilization | B17: =AVERAGEIFS(Calc_Stations!$K$2:$K$38,Calc_Stations!$A$2:$A$38,B$1) -> 0.57810199 | C17: =AVERAGEIFS(Calc_Stations!$K$2:$K$38,Calc_Stations!$A$2:$A$38,C$1) -> 0.94038141 | D17: =AVERAGEIFS(Calc_Stations!$K$2:$K$38,Calc_Stations!$A$2:$A$38,D$1) -> 0.64461025 | E17: =AVERAGEIFS(Calc_Stations!$K$2:$K$38,Calc_Stations!$A$2:$A$38,E$1) -> 0.6206336 | F17: =AVERAGEIFS(Calc_Stations!$K$2:$K$38,Calc_Stations!$A$2:$A$38,F$1) -> 0.78390163 | G17: =AVERAGEIFS(Calc_Stations!$K$2:$K$38,Calc_Stations!$A$2:$A$38,G$1) -> 0.65787411 | H17: =AVERAGEIFS(Calc_Stations!$K$2:$K$38,Calc_Stations!$A$2:$A$38,H$1) -> 0.47584827 | I17: =AVERAGEIFS(Calc_Stations!$K$2:$K$38,Calc_Stations!$A$2:$A$38,I$1) -> 0.51237182 | J17: %
A18: Real avg utilization | B18: =AVERAGEIFS(Calc_Stations!$L$2:$L$38,Calc_Stations!$A$2:$A$38,B$1) -> 0.55656733 | C18: =AVERAGEIFS(Calc_Stations!$L$2:$L$38,Calc_Stations!$A$2:$A$38,C$1) -> 0.90500828 | D18: =AVERAGEIFS(Calc_Stations!$L$2:$L$38,Calc_Stations!$A$2:$A$38,D$1) -> 0.60310013 | E18: =AVERAGEIFS(Calc_Stations!$L$2:$L$38,Calc_Stations!$A$2:$A$38,E$1) -> 0.60310013 | F18: =AVERAGEIFS(Calc_Stations!$L$2:$L$38,Calc_Stations!$A$2:$A$38,F$1) -> 0.70808614 | G18: =AVERAGEIFS(Calc_Stations!$L$2:$L$38,Calc_Stations!$A$2:$A$38,G$1) -> 0.69496738 | H18: =AVERAGEIFS(Calc_Stations!$L$2:$L$38,Calc_Stations!$A$2:$A$38,H$1) -> 0.5332778 | I18: =AVERAGEIFS(Calc_Stations!$L$2:$L$38,Calc_Stations!$A$2:$A$38,I$1) -> 0.5332778 | J18: %
A19: Utilization deviation | B19: =(B17-B18)*100 -> 2.1534658 | C19: =(C17-C18)*100 -> 3.5373131 | D19: =(D17-D18)*100 -> 4.1510129 | E19: =(E17-E18)*100 -> 1.7533472 | F19: =(F17-F18)*100 -> 7.5815482 | G19: =(G17-G18)*100 -> -3.7093267 | H19: =(H17-H18)*100 -> -5.7429531 | I19: =(I17-I18)*100 -> -2.0905979 | J19: pp
A20: COMPONENTS
A21: Sim. target components | B21: =SUMIFS(Calc_Components!$F$2:$F$83,Calc_Components!$A$2:$A$83,B$1,Calc_Components!$C$2:$C$83,"a") -> 69 | C21: =SUMIFS(Calc_Components!$F$2:$F$83,Calc_Components!$A$2:$A$83,C$1,Calc_Components!$C$2:$C$83,"a") -> 106 | D21: =SUMIFS(Calc_Components!$F$2:$F$83,Calc_Components!$A$2:$A$83,D$1,Calc_Components!$C$2:$C$83,"a") -> 118 | E21: =SUMIFS(Calc_Components!$F$2:$F$83,Calc_Components!$A$2:$A$83,E$1,Calc_Components!$C$2:$C$83,"a") -> 97 | F21: =SUMIFS(Calc_Components!$F$2:$F$83,Calc_Components!$A$2:$A$83,F$1,Calc_Components!$C$2:$C$83,"a") -> 100 | G21: =SUMIFS(Calc_Components!$F$2:$F$83,Calc_Components!$A$2:$A$83,G$1,Calc_Components!$C$2:$C$83,"a") -> 107 | H21: =SUMIFS(Calc_Components!$F$2:$F$83,Calc_Components!$A$2:$A$83,H$1,Calc_Components!$C$2:$C$83,"a") -> 76 | I21: =SUMIFS(Calc_Components!$F$2:$F$83,Calc_Components!$A$2:$A$83,I$1,Calc_Components!$C$2:$C$83,"a") -> 85 | J21: pcs
A22: Real target components | B22: =SUMIFS(Calc_Components!$H$2:$H$83,Calc_Components!$A$2:$A$83,B$1,Calc_Components!$C$2:$C$83,"a") -> 72 | C22: =SUMIFS(Calc_Components!$H$2:$H$83,Calc_Components!$A$2:$A$83,C$1,Calc_Components!$C$2:$C$83,"a") -> 110 | D22: =SUMIFS(Calc_Components!$H$2:$H$83,Calc_Components!$A$2:$A$83,D$1,Calc_Components!$C$2:$C$83,"a") -> 118 | E22: =SUMIFS(Calc_Components!$H$2:$H$83,Calc_Components!$A$2:$A$83,E$1,Calc_Components!$C$2:$C$83,"a") -> 118 | F22: =SUMIFS(Calc_Components!$H$2:$H$83,Calc_Components!$A$2:$A$83,F$1,Calc_Components!$C$2:$C$83,"a") -> 103 | G22: =SUMIFS(Calc_Components!$H$2:$H$83,Calc_Components!$A$2:$A$83,G$1,Calc_Components!$C$2:$C$83,"a") -> 107 | H22: =SUMIFS(Calc_Components!$H$2:$H$83,Calc_Components!$A$2:$A$83,H$1,Calc_Components!$C$2:$C$83,"a") -> 87 | I22: =SUMIFS(Calc_Components!$H$2:$H$83,Calc_Components!$A$2:$A$83,I$1,Calc_Components!$C$2:$C$83,"a") -> 87 | J22: pcs
A23: Component count deviation | B23: =(B21-B22)/B22 -> -0.041666667 | C23: =(C21-C22)/C22 -> -0.036363636 | D23: =(D21-D22)/D22 -> 0 | E23: =(E21-E22)/E22 -> -0.1779661 | F23: =(F21-F22)/F22 -> -0.029126214 | G23: =(G21-G22)/G22 -> 0 | H23: =(H21-H22)/H22 -> -0.12643678 | I23: =(I21-I22)/I22 -> -0.022988506 | J23: %
A24: Sim. remaining parts | B24: =SUMIFS(Calc_Components!$F$2:$F$83,Calc_Components!$A$2:$A$83,B$1,Calc_Components!$C$2:$C$83,"b") -> 9 | C24: =SUMIFS(Calc_Components!$F$2:$F$83,Calc_Components!$A$2:$A$83,C$1,Calc_Components!$C$2:$C$83,"b") -> 7 | D24: =SUMIFS(Calc_Components!$F$2:$F$83,Calc_Components!$A$2:$A$83,D$1,Calc_Components!$C$2:$C$83,"b") -> 7 | E24: =SUMIFS(Calc_Components!$F$2:$F$83,Calc_Components!$A$2:$A$83,E$1,Calc_Components!$C$2:$C$83,"b") -> 5 | F24: =SUMIFS(Calc_Components!$F$2:$F$83,Calc_Components!$A$2:$A$83,F$1,Calc_Components!$C$2:$C$83,"b") -> 5 | G24: =SUMIFS(Calc_Components!$F$2:$F$83,Calc_Components!$A$2:$A$83,G$1,Calc_Components!$C$2:$C$83,"b") -> 10 | H24: =SUMIFS(Calc_Components!$F$2:$F$83,Calc_Components!$A$2:$A$83,H$1,Calc_Components!$C$2:$C$83,"b") -> 6 | I24: =SUMIFS(Calc_Components!$F$2:$F$83,Calc_Components!$A$2:$A$83,I$1,Calc_Components!$C$2:$C$83,"b") -> 8 | J24: pcs
A25: Real remaining parts | B25: =SUMIFS(Calc_Components!$H$2:$H$83,Calc_Components!$A$2:$A$83,B$1,Calc_Components!$C$2:$C$83,"b") -> 10 | C25: =SUMIFS(Calc_Components!$H$2:$H$83,Calc_Components!$A$2:$A$83,C$1,Calc_Components!$C$2:$C$83,"b") -> 8 | D25: =SUMIFS(Calc_Components!$H$2:$H$83,Calc_Components!$A$2:$A$83,D$1,Calc_Components!$C$2:$C$83,"b") -> 5 | E25: =SUMIFS(Calc_Components!$H$2:$H$83,Calc_Components!$A$2:$A$83,E$1,Calc_Components!$C$2:$C$83,"b") -> 5 | F25: =SUMIFS(Calc_Components!$H$2:$H$83,Calc_Components!$A$2:$A$83,F$1,Calc_Components!$C$2:$C$83,"b") -> 6 | G25: =SUMIFS(Calc_Components!$H$2:$H$83,Calc_Components!$A$2:$A$83,G$1,Calc_Components!$C$2:$C$83,"b") -> 10 | H25: =SUMIFS(Calc_Components!$H$2:$H$83,Calc_Components!$A$2:$A$83,H$1,Calc_Components!$C$2:$C$83,"b") -> 10 | I25: =SUMIFS(Calc_Components!$H$2:$H$83,Calc_Components!$A$2:$A$83,I$1,Calc_Components!$C$2:$C$83,"b") -> 10 | J25: pcs
A26: Remaining parts deviation | B26: =IF(B25=0,"",(B24-B25)/B25) -> -0.1 | C26: =IF(C25=0,"",(C24-C25)/C25) -> -0.125 | D26: =IF(D25=0,"",(D24-D25)/D25) -> 0.4 | E26: =IF(E25=0,"",(E24-E25)/E25) -> 0 | F26: =IF(F25=0,"",(F24-F25)/F25) -> -0.16666667 | G26: =IF(G25=0,"",(G24-G25)/G25) -> 0 | H26: =IF(H25=0,"",(H24-H25)/H25) -> -0.4 | I26: =IF(I25=0,"",(I24-I25)/I25) -> -0.2 | J26: %
A27: ASSESSMENT
A28: Assessment (±20 %, utilization ±20 pp) | B28: =IF(AND(ABS(B14)<=0.2,ABS(B19)<=20,ABS(B23)<=0.2),"Pass","Fail") -> Pass | C28: =IF(AND(ABS(C14)<=0.2,ABS(C19)<=20,ABS(C23)<=0.2),"Pass","Fail") -> Pass | D28: =IF(AND(ABS(D14)<=0.2,ABS(D19)<=20,ABS(D23)<=0.2),"Pass","Fail") -> Fail | E28: =IF(AND(ABS(E14)<=0.2,ABS(E19)<=20,ABS(E23)<=0.2),"Pass","Fail") -> Pass | F28: =IF(AND(ABS(F14)<=0.2,ABS(F19)<=20,ABS(F23)<=0.2),"Pass","Fail") -> Pass | G28: =IF(AND(ABS(G14)<=0.2,ABS(G19)<=20,ABS(G23)<=0.2),"Pass","Fail") -> Pass | H28: =IF(AND(ABS(H14)<=0.2,ABS(H19)<=20,ABS(H23)<=0.2),"Pass","Fail") -> Pass | I28: =IF(AND(ABS(I14)<=0.2,ABS(I19)<=20,ABS(I23)<=0.2),"Pass","Fail") -> Pass

Sheet Runs
A1: Run | B1: Scenario | C1: Experiment | D1: Output folder | E1: Start date
A2: S1 | B2: 1 | C2: exp12_scenario_01 | D2: output\scenario_01 | E2: 45664
A3: S2 | B3: 2 | C3: exp13_scenario_02 | D3: output\scenario_02 | E3: 45660
A4: S3 | B4: 3 | C4: exp14_scenario_03 | D4: output\scenario_03 | E4: 45670
A5: S3s | B5: 3 | C5: exp14_scenario_03_sensitivity | D5: output\scenario_03_sensitivity | E5: 45670
A6: S4 | B6: 4 | C6: exp15_scenario_04 | D6: output\scenario_04 | E6: 45665
A7: S5 | B7: 5 | C7: exp16_scenario_05 | D7: output\scenario_05 | E7: 45666
A8: S6 | B8: 6 | C8: exp17_scenario_06 | D8: output\scenario_06 | E8: 45667
A9: S6s | B9: 6 | C9: exp17_scenario_06_sensitivity | D9: output\scenario_06_sensitivity | E9: 45667

Sheet Scenarios
A1: Scenario | B1: Real components | C1: Real utilization (%) | D1: Factory-complete POs
A2: 1 | B2: =SUMIFS(Factory_Components!$H$2:$H$62,Factory_Components!$A$2:$A$62,A2,Factory_Components!$B$2:$B$62,"a") -> 72 | C2: =AVERAGEIFS(Factory_Stations!$F$2:$F$28,Factory_Stations!$A$2:$A$28,A2) -> 55.656733 | D2: =COUNTIFS(Factory_PO!$A$2:$A$61,A2,Factory_PO!$D$2:$D$61,"<>") -> 10
A3: 2 | B3: =SUMIFS(Factory_Components!$H$2:$H$62,Factory_Components!$A$2:$A$62,A3,Factory_Components!$B$2:$B$62,"a") -> 110 | C3: =AVERAGEIFS(Factory_Stations!$F$2:$F$28,Factory_Stations!$A$2:$A$28,A3) -> 90.500828 | D3: =COUNTIFS(Factory_PO!$A$2:$A$61,A3,Factory_PO!$D$2:$D$61,"<>") -> 8
A4: 3 | B4: =SUMIFS(Factory_Components!$H$2:$H$62,Factory_Components!$A$2:$A$62,A4,Factory_Components!$B$2:$B$62,"a") -> 118 | C4: =AVERAGEIFS(Factory_Stations!$F$2:$F$28,Factory_Stations!$A$2:$A$28,A4) -> 60.310013 | D4: =COUNTIFS(Factory_PO!$A$2:$A$61,A4,Factory_PO!$D$2:$D$61,"<>") -> 5
A5: 4 | B5: =SUMIFS(Factory_Components!$H$2:$H$62,Factory_Components!$A$2:$A$62,A5,Factory_Components!$B$2:$B$62,"a") -> 103 | C5: =AVERAGEIFS(Factory_Stations!$F$2:$F$28,Factory_Stations!$A$2:$A$28,A5) -> 70.808614 | D5: =COUNTIFS(Factory_PO!$A$2:$A$61,A5,Factory_PO!$D$2:$D$61,"<>") -> 6
A6: 5 | B6: =SUMIFS(Factory_Components!$H$2:$H$62,Factory_Components!$A$2:$A$62,A6,Factory_Components!$B$2:$B$62,"a") -> 107 | C6: =AVERAGEIFS(Factory_Stations!$F$2:$F$28,Factory_Stations!$A$2:$A$28,A6) -> 69.496738 | D6: =COUNTIFS(Factory_PO!$A$2:$A$61,A6,Factory_PO!$D$2:$D$61,"<>") -> 10
A7: 6 | B7: =SUMIFS(Factory_Components!$H$2:$H$62,Factory_Components!$A$2:$A$62,A7,Factory_Components!$B$2:$B$62,"a") -> 87 | C7: =AVERAGEIFS(Factory_Stations!$F$2:$F$28,Factory_Stations!$A$2:$A$28,A7) -> 53.32778 | D7: =COUNTIFS(Factory_PO!$A$2:$A$61,A7,Factory_PO!$D$2:$D$61,"<>") -> 8

Sheet raw_outputtable
A1: Run | B1: caseID | C1: objectID | D1: object_type | E1: object_name | F1: delivery_time | G1: output_time | H1: Code | I1: Group | J1: Delivery (min) | K1: Output (min)
A2: S1 | B2: 1 | C2: 1_BOSP_1 | D2: component | E2: car_rd_BOSP | F2: 45664 | G2: 45664.063 | H2: =MID(E2,8,100) -> BOSP | I2: =IF(H2="CORE","CHS",H2) -> BOSP | J2: =(F2-VLOOKUP($A2,Runs!$A$2:$E$9,5,FALSE()))*1440 -> 0 | K2: =(G2-VLOOKUP($A2,Runs!$A$2:$E$9,5,FALSE()))*1440 -> 90.866667
A3: S1 | B3: 1 | C3: 1_BOSP_2 | D3: component | E3: car_rd_BOSP | F3: 45664 | G3: 45664.084 | H3: =MID(E3,8,100) -> BOSP | I3: =IF(H3="CORE","CHS",H3) -> BOSP | J3: =(F3-VLOOKUP($A3,Runs!$A$2:$E$9,5,FALSE()))*1440 -> 0 | K3: =(G3-VLOOKUP($A3,Runs!$A$2:$E$9,5,FALSE()))*1440 -> 121.53333
A4: S1 | B4: 1 | C4: 1_RT_1 | D4: component | E4: car_rd_RT | F4: 45664 | G4: 45664.126 | H4: =MID(E4,8,100) -> RT | I4: =IF(H4="CORE","CHS",H4) -> RT | J4: =(F4-VLOOKUP($A4,Runs!$A$2:$E$9,5,FALSE()))*1440 -> 0 | K4: =(G4-VLOOKUP($A4,Runs!$A$2:$E$9,5,FALSE()))*1440 -> 180.86667
A5: S1 | B5: 1 | C5: 1_RT_2 | D5: component | E5: car_rd_RT | F5: 45664 | G5: 45664.148 | H5: =MID(E5,8,100) -> RT | I5: =IF(H5="CORE","CHS",H5) -> RT | J5: =(F5-VLOOKUP($A5,Runs!$A$2:$E$9,5,FALSE()))*1440 -> 0 | K5: =(G5-VLOOKUP($A5,Runs!$A$2:$E$9,5,FALSE()))*1440 -> 213.4
A6: S1 | B6: 2 | C6: 2_BOSP_1 | D6: component | E6: car_rd_BOSP | F6: 45664.083 | G6: 45664.168 | H6: =MID(E6,8,100) -> BOSP | I6: =IF(H6="CORE","CHS",H6) -> BOSP | J6: =(F6-VLOOKUP($A6,Runs!$A$2:$E$9,5,FALSE()))*1440 -> 120 | K6: =(G6-VLOOKUP($A6,Runs!$A$2:$E$9,5,FALSE()))*1440 -> 241.53333
A7: S1 | B7: 2 | C7: 2_BOSP_2 | D7: component | E7: car_rd_BOSP | F7: 45664.083 | G7: 45664.209 | H7: =MID(E7,8,100) -> BOSP | I7: =IF(H7="CORE","CHS",H7) -> BOSP | J7: =(F7-VLOOKUP($A7,Runs!$A$2:$E$9,5,FALSE()))*1440 -> 120 | K7: =(G7-VLOOKUP($A7,Runs!$A$2:$E$9,5,FALSE()))*1440 -> 300.86667
A8: S1 | B8: 2 | C8: 2_RT_1 | D8: component | E8: car_rd_RT | F8: 45664.083 | G8: 45664.23 | H8: =MID(E8,8,100) -> RT | I8: =IF(H8="CORE","CHS",H8) -> RT | J8: =(F8-VLOOKUP($A8,Runs!$A$2:$E$9,5,FALSE()))*1440 -> 120 | K8: =(G8-VLOOKUP($A8,Runs!$A$2:$E$9,5,FALSE()))*1440 -> 331.53333
A9: S1 | B9: 1 | C9: 1_CORE | D9: component | E9: car_rd_CORE | F9: 45664 | G9: 45664.252 | H9: =MID(E9,8,100) -> CORE | I9: =IF(H9="CORE","CHS",H9) -> CHS | J9: =(F9-VLOOKUP($A9,Runs!$A$2:$E$9,5,FALSE()))*1440 -> 0 | K9: =(G9-VLOOKUP($A9,Runs!$A$2:$E$9,5,FALSE()))*1440 -> 363.4
A10: S1 | B10: 2 | C10: 2_RT_2 | D10: component | E10: car_rd_RT | F10: 45664.083 | G10: 45664.273 | H10: =MID(E10,8,100) -> RT | I10: =IF(H10="CORE","CHS",H10) -> RT | J10: =(F10-VLOOKUP($A10,Runs!$A$2:$E$9,5,FALSE()))*1440 -> 120 | K10: =(G10-VLOOKUP($A10,Runs!$A$2:$E$9,5,FALSE()))*1440 -> 393.4
A11: S1 | B11: 3 | C11: 3_BOSP_1 | D11: component | E11: car_rd_BOSP | F11: 45664.167 | G11: 45664.292 | H11: =MID(E11,8,100) -> BOSP | I11: =IF(H11="CORE","CHS",H11) -> BOSP | J11: =(F11-VLOOKUP($A11,Runs!$A$2:$E$9,5,FALSE()))*1440 -> 240 | K11: =(G11-VLOOKUP($A11,Runs!$A$2:$E$9,5,FALSE()))*1440 -> 420.86667
A12: S1 | B12: 3 | C12: 3_BOSP_2 | D12: component | E12: car_rd_BOSP | F12: 45664.167 | G12: 45664.314 | H12: =MID(E12,8,100) -> BOSP | I12: =IF(H12="CORE","CHS",H12) -> BOSP | J12: =(F12-VLOOKUP($A12,Runs!$A$2:$E$9,5,FALSE()))*1440 -> 240 | K12: =(G12-VLOOKUP($A12,Runs!$A$2:$E$9,5,FALSE()))*1440 -> 451.53333
A13: S1 | B13: 1 | C13: 1_BSA_1 | D13: component | E13: car_rd_BSA | F13: 45664 | G13: 45664.315 | H13: =MID(E13,8,100) -> BSA | I13: =IF(H13="CORE","CHS",H13) -> BSA | J13: =(F13-VLOOKUP($A13,Runs!$A$2:$E$9,5,FALSE()))*1440 -> 0 | K13: =(G13-VLOOKUP($A13,Runs!$A$2:$E$9,5,FALSE()))*1440 -> 453.06667
... A816: S6s | B816: 8 | C816: 8_CHS | D816: component | E816: car_hd_CHS | F816: 45667.438 | G816: 45668.627 | H816: =MID(E816,8,100) -> CHS | I816: =IF(H816="CORE","CHS",H816) -> CHS | J816: =(F816-VLOOKUP($A816,Runs!$A$2:$E$9,5,FALSE()))*1440 -> 630 | K816: =(G816-VLOOKUP($A816,Runs!$A$2:$E$9,5,FALSE()))*1440 -> 2343.4

Sheet raw_casetable
A1: Run | B1: caseID | C1: product_type | D1: delivery_time | E1: target_components | F1: N target | G1: Key
A2: S1 | B2: 1 | C2: car_rd | D2: 2025-01-07T00:00:00 | E2: {"BOSP": 2, "RT": 2, "CORE": 1, "BSA": 2, "RAX_RD": 1} | F2: 8 | G2: =A2&"|"&B2 -> S1|1
A3: S1 | B3: 2 | C3: car_rd | D3: 2025-01-07T02:00:00 | E3: {"BOSP": 2, "RT": 2, "CORE": 1, "BSA": 2, "RAX_RD": 1} | F3: 8 | G3: =A3&"|"&B3 -> S1|2
A4: S1 | B4: 3 | C4: car_rd | D4: 2025-01-07T04:00:00 | E4: {"BOSP": 2, "RT": 2, "CORE": 1, "BSA": 2, "RAX_RD": 1} | F4: 8 | G4: =A4&"|"&B4 -> S1|3
A5: S1 | B5: 4 | C5: car_tl | D5: 2025-01-07T06:00:00 | E5: {"BOSP": 2, "BAT": 1, "RT": 2, "FT": 2, "CRE": 1} | F5: 8 | G5: =A5&"|"&B5 -> S1|4
A6: S1 | B6: 5 | C6: car_sa | D6: 2025-01-07T09:00:00 | E6: {"RT": 2, "FT": 2, "SSA": 2, "BSA": 2, "CSEB-NABS": 1} | F6: 9 | G6: =A6&"|"&B6 -> S1|5
A7: S1 | B7: 6 | C7: car_rd | D7: 2025-01-07T10:00:00 | E7: {"BOSP": 2, "RT": 2, "CORE": 1, "BSA": 2, "RAX_RD": 1} | F7: 8 | G7: =A7&"|"&B7 -> S1|6
A8: S1 | B8: 7 | C8: car_rd | D8: 2025-01-07T12:00:00 | E8: {"BOSP": 2, "RT": 2, "CORE": 1, "BSA": 2, "RAX_RD": 1} | F8: 8 | G8: =A8&"|"&B8 -> S1|7
A9: S1 | B9: 8 | C9: car_tl | D9: 2025-01-07T14:30:00 | E9: {"BOSP": 2, "BAT": 1, "RT": 2, "FT": 2, "CRE": 1} | F9: 8 | G9: =A9&"|"&B9 -> S1|8
A10: S1 | B10: 9 | C10: car_rd | D10: 2025-01-07T18:30:00 | E10: {"BOSP": 2, "RT": 2, "CORE": 1, "BSA": 2, "RAX_RD": 1} | F10: 8 | G10: =A10&"|"&B10 -> S1|9
A11: S1 | B11: 10 | C11: car_sa | D11: 2025-01-08T06:00:00 | E11: {"RT": 2, "FT": 2, "SSA": 2, "BSA": 2, "CSEB-NABS": 1} | F11: 9 | G11: =A11&"|"&B11 -> S1|10
A12: S2 | B12: 1 | C12: car_hd | D12: 2025-01-03T00:00:00 | E12: {"BOSP": 2, "BAT": 1, "RT": 2, "FT": 2, "FRONT_AXIS_GROUP_SSA": 2, "FRONT_AXIS_GROUP_FAX": 1, "REAR_AXIS_GROUP_CHS": 1, "REAR_AXIS_GROUP_BSA": 2, "REAR_AXIS_GROUP_RAX_HD": 1} | F12: 14 | G12: =A12&"|"&B12 -> S2|1
A13: S2 | B13: 2 | C13: car_hd | D13: 2025-01-03T01:00:00 | E13: {"BOSP": 2, "BAT": 1, "RT": 2, "FT": 2, "FRONT_AXIS_GROUP_SSA": 2, "FRONT_AXIS_GROUP_FAX": 1, "REAR_AXIS_GROUP_CHS": 1, "REAR_AXIS_GROUP_BSA": 2, "REAR_AXIS_GROUP_RAX_HD": 1} | F13: 14 | G13: =A13&"|"&B13 -> S2|2
... A81: S6s | B81: 10 | C81: car_sa | D81: 2025-01-10T13:30:00 | E81: {"RT": 2, "FT": 2, "SSA": 2, "BSA": 2, "CSEB-NABS": 1} | F81: 9 | G81: =A81&"|"&B81 -> S6s|10

Sheet raw_comp_PTA
A1: Run | B1: caseID | C1: product_type | D1: delivery_time | E1: exit_time | F1: throughput_time | G1: active_production_time | H1: value_creating_time_VT | I1: nonvalue_creating_time_NCT | J1: Key
A2: S1 | B2: 1 | C2: car_rd | D2: 0 | E2: 571.53 | F2: 571.53 | G2: 541.33 | H2: 445.1 | I2: 478.03 | J2: =A2&"|"&B2 -> S1|1
A3: S1 | B3: 2 | C3: car_rd | D3: 120 | E3: 753.07 | F3: 633.07 | G3: 601.14 | H3: 445.1 | I3: 570.57 | J3: =A3&"|"&B3 -> S1|2
A4: S1 | B4: 3 | C4: car_rd | D4: 240 | E4: 901.53 | F4: 661.53 | G4: 629.6 | H4: 445.1 | I4: 482.57 | J4: =A4&"|"&B4 -> S1|3
A5: S1 | B5: 4 | C5: car_tl | D5: 360 | E5: 961.53 | F5: 601.53 | G5: 566.2 | H5: 374.1 | I5: 493.23 | J5: =A5&"|"&B5 -> S1|4
A6: S1 | B6: 5 | C6: car_sa | D6: 540 | E6: 1444.93 | F6: 904.93 | G6: 871.46 | H6: 444.1 | I6: 781.23 | J6: =A6&"|"&B6 -> S1|5
A7: S1 | B7: 6 | C7: car_rd | D7: 600 | E7: 1621.53 | F7: 1021.53 | G7: 986.53 | H7: 445.1 | I7: 922.9 | J7: =A7&"|"&B7 -> S1|6
A8: S1 | B8: 7 | C8: car_rd | D8: 720 | E8: 1801.53 | F8: 1081.53 | G8: 1046.53 | H8: 445.1 | I8: 987.83 | J8: =A8&"|"&B8 -> S1|7
A9: S1 | B9: 8 | C9: car_tl | D9: 870 | E9: 1860.87 | F9: 990.87 | G9: 957.4 | H9: 374.1 | I9: 913.1 | J9: =A9&"|"&B9 -> S1|8
A10: S1 | B10: 9 | C10: car_rd | D10: 1110 | E10: 2341.53 | F10: 1231.53 | G10: 1198.06 | H10: 445.1 | I10: 1107.83 | J10: =A10&"|"&B10 -> S1|9
A11: S1 | B11: 10 | C11: car_sa | D11: 1800 | E11: 2371.53 | F11: 571.53 | G11: 538.06 | H11: 236 | I11: 422.87 | J11: =A11&"|"&B11 -> S1|10
A12: S2 | B12: 1 | C12: car_hd | D12: 0 | E12: 1171.53 | F12: 1171.53 | G12: 1141.33 | H12: 1089.3 | I12: 594.5 | J12: =A12&"|"&B12 -> S2|1
A13: S2 | B13: 2 | C13: car_hd | D13: 60 | E13: 1233.07 | F13: 1173.07 | G13: 1140.27 | H13: 1089.3 | I13: 591.73 | J13: =A13&"|"&B13 -> S2|2
... A81: S6s | B81: 10 | C81: car_sa | D81: 810 | E81: 2131.53 | F81: 1321.53 | G81: 1287.16 | H81: 525.1 | I81: 1091.77 | J81: =A81&"|"&B81 -> S6s|10

Sheet raw_comp_PTA_stations
A1: Run | B1: caseID | C1: Station | D1: VT | E1: NCT
A2: S1 | B2: 1 | C2: logistics_resource_01 | D2: 0 | E2: 387.8
A3: S1 | B3: 1 | C3: ws-03_S1toS4 | D3: 168 | E3: 10.73
A4: S1 | B4: 1 | C4: ws-04_S5S7 | D4: 129 | E4: 19.3
A5: S1 | B5: 1 | C5: ws-05_S6S8 | D5: 148.1 | E5: 60.2
A6: S1 | B6: 2 | C6: logistics_resource_01 | D6: 0 | E6: 425.47
A7: S1 | B7: 2 | C7: ws-03_S1toS4 | D7: 168 | E7: 69
A8: S1 | B8: 2 | C8: ws-04_S5S7 | D8: 129 | E8: 19.3
A9: S1 | B9: 2 | C9: ws-05_S6S8 | D9: 148.1 | E9: 56.8
A10: S1 | B10: 3 | C10: logistics_resource_01 | D10: 0 | E10: 304.23
A11: S1 | B11: 3 | C11: ws-03_S1toS4 | D11: 168 | E11: 99
A12: S1 | B12: 3 | C12: ws-04_S5S7 | D12: 129 | E12: 19.3
A13: S1 | B13: 3 | C13: ws-05_S6S8 | D13: 148.1 | E13: 60.03
... A461: S6s | B461: 10 | C461: ws-05_S6S8 | D461: 295.1 | E461: 152.47

Sheet raw_station_stats_absolute
A1: Run | B1: station | C1: total_available_time | D1: busy_time | E1: blocked_time | F1: waiting_time | G1: failure_time | H1: closed_time | I1: product_count | J1: Key
A2: S1 | B2: ws-03_S1toS4 | C2: 2399 | D2: 2110.2 | E2: 5.6 | F2: 283.2 | G2: 0 | H2: 0 | I2: 10 | J2: =A2&"|"&B2 -> S1|ws-03_S1toS4
A3: S1 | B3: ws-04_S5S7 | C3: 2399 | D3: 775.2 | E3: 1.2 | F3: 1622.6 | G3: 0 | H3: 0 | I3: 6 | J3: =A3&"|"&B3 -> S1|ws-04_S5S7
A4: S1 | B4: ws-05_S6S8 | C4: 2399 | D4: 1275.2 | E4: 2.4 | F4: 1121.4 | G4: 0 | H4: 0 | I4: 7 | J4: =A4&"|"&B4 -> S1|ws-05_S6S8
A5: S1 | B5: logistics_resource_01 | C5: 2399 | D5: 76 | E5: 0 | F5: 2323 | G5: 0 | H5: 0 | I5: 102 | J5: =A5&"|"&B5 -> S1|logistics_resource_01
A6: S2 | B6: ws-01_S1toS8 | C6: 2399 | D6: 2364.8 | E6: 3 | F6: 31.3 | G6: 0 | H6: 0 | I6: 8 | J6: =A6&"|"&B6 -> S2|ws-01_S1toS8
A7: S2 | B7: ws-02_S1toS8 | C7: 2399 | D7: 2301.4 | E7: 3 | F7: 94.6 | G7: 0 | H7: 0 | I7: 8 | J7: =A7&"|"&B7 -> S2|ws-02_S1toS8
A8: S2 | B8: ws-03_S1toS8 | C8: 2399 | D8: 2179 | E8: 2.8 | F8: 217.2 | G8: 0 | H8: 0 | I8: 8 | J8: =A8&"|"&B8 -> S2|ws-03_S1toS8
A9: S2 | B9: ws-04_S1toS8 | C9: 2399 | D9: 2178.7 | E9: 2.6 | F9: 217.7 | G9: 0 | H9: 0 | I9: 7 | J9: =A9&"|"&B9 -> S2|ws-04_S1toS8
A10: S2 | B10: logistics_resource_01 | C10: 2399 | D10: 89.7 | E10: 0 | F10: 2309.4 | G10: 0 | H10: 0 | I10: 123 | J10: =A10&"|"&B10 -> S2|logistics_resource_01
A11: S3 | B11: ws-01_S1S2 | C11: 2399 | D11: 1092 | E11: 4 | F11: 1303 | G11: 0 | H11: 0 | I11: 10 | J11: =A11&"|"&B11 -> S3|ws-01_S1S2
A12: S3 | B12: ws-02_S3S4 | C12: 2399 | D12: 1882 | E12: 5 | F12: 512 | G12: 0 | H12: 0 | I12: 10 | J12: =A12&"|"&B12 -> S3|ws-02_S3S4
A13: S3 | B13: ws-03_S5 | C13: 2399 | D13: 1703 | E13: 2 | F13: 694 | G13: 0 | H13: 0 | I13: 10 | J13: =A13&"|"&B13 -> S3|ws-03_S5
... A46: S6s | B46: logistics_resource_01 | C46: 2399 | D46: 106.6 | E46: 0 | F46: 2292.4 | G46: 0 | H46: 0 | I46: 131 | J46: =A46&"|"&B46 -> S6s|logistics_resource_01

Sheet raw_eventlog_created_objects
A1: Run | B1: object_id | C1: resource_id | D1: timestamp | E1: Code | F1: Group | G1: Target component
A2: S1 | B2: comp_001_BOSP_1 | C2: ws-03_S1toS4 | D2: 2025-01-07T01:10:28 | E2: =IF(ISNUMBER(--RIGHT(B2,1)),MID(B2,10,LEN(B2)-11),MID(B2,10,100)) -> BOSP | F2: =IF(E2="CORE","CHS",E2) -> BOSP | G2: =IF(COUNTIFS(Factory_Components!$A$2:$A$61,VLOOKUP(A2,Runs!$A$2:$B$9,2,FALSE()),Factory_Components!$B$2:$B$61,"a",Factory_Components!$D$2:$D$61,F2)>0,1,0) -> 1
A3: S1 | B3: comp_001_BOSP_2 | C3: ws-03_S1toS4 | D3: 2025-01-07T01:49:34 | E3: =IF(ISNUMBER(--RIGHT(B3,1)),MID(B3,10,LEN(B3)-11),MID(B3,10,100)) -> BOSP | F3: =IF(E3="CORE","CHS",E3) -> BOSP | G3: =IF(COUNTIFS(Factory_Components!$A$2:$A$61,VLOOKUP(A3,Runs!$A$2:$B$9,2,FALSE()),Factory_Components!$B$2:$B$61,"a",Factory_Components!$D$2:$D$61,F3)>0,1,0) -> 1
A4: S1 | B4: comp_001_RT_1 | C4: ws-03_S1toS4 | D4: 2025-01-07T02:34:40 | E4: =IF(ISNUMBER(--RIGHT(B4,1)),MID(B4,10,LEN(B4)-11),MID(B4,10,100)) -> RT | F4: =IF(E4="CORE","CHS",E4) -> RT | G4: =IF(COUNTIFS(Factory_Components!$A$2:$A$61,VLOOKUP(A4,Runs!$A$2:$B$9,2,FALSE()),Factory_Components!$B$2:$B$61,"a",Factory_Components!$D$2:$D$61,F4)>0,1,0) -> 1
A5: S1 | B5: comp_001_RT_2 | C5: ws-03_S1toS4 | D5: 2025-01-07T03:19:46 | E5: =IF(ISNUMBER(--RIGHT(B5,1)),MID(B5,10,LEN(B5)-11),MID(B5,10,100)) -> RT | F5: =IF(E5="CORE","CHS",E5) -> RT | G5: =IF(COUNTIFS(Factory_Components!$A$2:$A$61,VLOOKUP(A5,Runs!$A$2:$B$9,2,FALSE()),Factory_Components!$B$2:$B$61,"a",Factory_Components!$D$2:$D$61,F5)>0,1,0) -> 1
A6: S1 | B6: comp_002_BOSP_1 | C6: ws-03_S1toS4 | D6: 2025-01-07T03:59:10 | E6: =IF(ISNUMBER(--RIGHT(B6,1)),MID(B6,10,LEN(B6)-11),MID(B6,10,100)) -> BOSP | F6: =IF(E6="CORE","CHS",E6) -> BOSP | G6: =IF(COUNTIFS(Factory_Components!$A$2:$A$61,VLOOKUP(A6,Runs!$A$2:$B$9,2,FALSE()),Factory_Components!$B$2:$B$61,"a",Factory_Components!$D$2:$D$61,F6)>0,1,0) -> 1
A7: S1 | B7: comp_002_BOSP_2 | C7: ws-03_S1toS4 | D7: 2025-01-07T04:38:16 | E7: =IF(ISNUMBER(--RIGHT(B7,1)),MID(B7,10,LEN(B7)-11),MID(B7,10,100)) -> BOSP | F7: =IF(E7="CORE","CHS",E7) -> BOSP | G7: =IF(COUNTIFS(Factory_Components!$A$2:$A$61,VLOOKUP(A7,Runs!$A$2:$B$9,2,FALSE()),Factory_Components!$B$2:$B$61,"a",Factory_Components!$D$2:$D$61,F7)>0,1,0) -> 1
A8: S1 | B8: comp_002_RT_1 | C8: ws-03_S1toS4 | D8: 2025-01-07T05:23:22 | E8: =IF(ISNUMBER(--RIGHT(B8,1)),MID(B8,10,LEN(B8)-11),MID(B8,10,100)) -> RT | F8: =IF(E8="CORE","CHS",E8) -> RT | G8: =IF(COUNTIFS(Factory_Components!$A$2:$A$61,VLOOKUP(A8,Runs!$A$2:$B$9,2,FALSE()),Factory_Components!$B$2:$B$61,"a",Factory_Components!$D$2:$D$61,F8)>0,1,0) -> 1
A9: S1 | B9: comp_001_CORE | C9: ws-04_S5S7 | D9: 2025-01-07T05:40:54 | E9: =IF(ISNUMBER(--RIGHT(B9,1)),MID(B9,10,LEN(B9)-11),MID(B9,10,100)) -> CORE | F9: =IF(E9="CORE","CHS",E9) -> CHS | G9: =IF(COUNTIFS(Factory_Components!$A$2:$A$61,VLOOKUP(A9,Runs!$A$2:$B$9,2,FALSE()),Factory_Components!$B$2:$B$61,"a",Factory_Components!$D$2:$D$61,F9)>0,1,0) -> 1
A10: S1 | B10: comp_002_RT_2 | C10: ws-03_S1toS4 | D10: 2025-01-07T06:08:28 | E10: =IF(ISNUMBER(--RIGHT(B10,1)),MID(B10,10,LEN(B10)-11),MID(B10,10,100)) -> RT | F10: =IF(E10="CORE","CHS",E10) -> RT | G10: =IF(COUNTIFS(Factory_Components!$A$2:$A$61,VLOOKUP(A10,Runs!$A$2:$B$9,2,FALSE()),Factory_Components!$B$2:$B$61,"a",Factory_Components!$D$2:$D$61,F10)>0,1,0) -> 1
A11: S1 | B11: comp_003_BOSP_1 | C11: ws-03_S1toS4 | D11: 2025-01-07T06:47:52 | E11: =IF(ISNUMBER(--RIGHT(B11,1)),MID(B11,10,LEN(B11)-11),MID(B11,10,100)) -> BOSP | F11: =IF(E11="CORE","CHS",E11) -> BOSP | G11: =IF(COUNTIFS(Factory_Components!$A$2:$A$61,VLOOKUP(A11,Runs!$A$2:$B$9,2,FALSE()),Factory_Components!$B$2:$B$61,"a",Factory_Components!$D$2:$D$61,F11)>0,1,0) -> 1
A12: S1 | B12: comp_001_BSA_1 | C12: ws-05_S6S8 | D12: 2025-01-07T07:15:54 | E12: =IF(ISNUMBER(--RIGHT(B12,1)),MID(B12,10,LEN(B12)-11),MID(B12,10,100)) -> BSA | F12: =IF(E12="CORE","CHS",E12) -> BSA | G12: =IF(COUNTIFS(Factory_Components!$A$2:$A$61,VLOOKUP(A12,Runs!$A$2:$B$9,2,FALSE()),Factory_Components!$B$2:$B$61,"a",Factory_Components!$D$2:$D$61,F12)>0,1,0) -> 1
A13: S1 | B13: comp_003_BOSP_2 | C13: ws-03_S1toS4 | D13: 2025-01-07T07:26:58 | E13: =IF(ISNUMBER(--RIGHT(B13,1)),MID(B13,10,LEN(B13)-11),MID(B13,10,100)) -> BOSP | F13: =IF(E13="CORE","CHS",E13) -> BOSP | G13: =IF(COUNTIFS(Factory_Components!$A$2:$A$61,VLOOKUP(A13,Runs!$A$2:$B$9,2,FALSE()),Factory_Components!$B$2:$B$61,"a",Factory_Components!$D$2:$D$61,F13)>0,1,0) -> 1
... A826: S6s | B826: comp_008_FAX | C826: ws-05_S6S8 | D826: 2025-01-11T15:50:38 | E826: =IF(ISNUMBER(--RIGHT(B826,1)),MID(B826,10,LEN(B826)-11),MID(B826,10,100)) -> FAX | F826: =IF(E826="CORE","CHS",E826) -> FAX | G826: =IF(COUNTIFS(Factory_Components!$A$2:$A$61,VLOOKUP(A826,Runs!$A$2:$B$9,2,FALSE()),Factory_Components!$B$2:$B$61,"a",Factory_Components!$D$2:$D$61,F826)>0,1,0) -> 1

Sheet Factory_PO
A1: Scenario | B1: PO | C1: Factory handling time | D1: Factory lead time | E1: Key
A2: 1 | B2: 1 | C2: 629 | D2: 586 | E2: =A2&"|"&B2 -> 1|1
A3: 1 | B3: 2 | C3: 482 | D3: 721 | E3: =A3&"|"&B3 -> 1|2
A4: 1 | B4: 3 | C4: 360 | D4: 721 | E4: =A4&"|"&B4 -> 1|3
A5: 1 | B5: 4 | C5: 402 | D5: 530 | E5: =A5&"|"&B5 -> 1|4
A6: 1 | B6: 5 | C6: 555 | D6: 976 | E6: =A6&"|"&B6 -> 1|5
A7: 1 | B7: 6 | C7: 480 | D7: 1231 | E7: =A7&"|"&B7 -> 1|6
A8: 1 | B8: 7 | C8: 383 | D8: 941 | E8: =A8&"|"&B8 -> 1|7
A9: 1 | B9: 8 | C9: 403 | D9: 931 | E9: =A9&"|"&B9 -> 1|8
A10: 1 | B10: 9 | C10: 285 | D10: 1082 | E10: =A10&"|"&B10 -> 1|9
A11: 1 | B11: 10 | C11: 330 | D11: 616 | E11: =A11&"|"&B11 -> 1|10
A12: 2 | B12: 1 | C12: 1155 | D12: 1231 | E12: =A12&"|"&B12 -> 2|1
A13: 2 | B13: 2 | C13: 1325 | D13: 1051 | E13: =A13&"|"&B13 -> 2|2
... A19: 2 | B19: 8 | C19: 930 | D19: 1786 | E19: =A19&"|"&B19 -> 2|8
A20: 2 | B20: 9 | C20: 149 | E20: =A20&"|"&B20 -> 2|9
A21: 2 | B21: 10 | C21: 165 | E21: =A21&"|"&B21 -> 2|10
A22: 3 | B22: 1 | C22: 910 | D22: 1066 | E22: =A22&"|"&B22 -> 3|1
A23: 3 | B23: 2 | C23: 752 | D23: 1636 | E23: =A23&"|"&B23 -> 3|2
A24: 3 | B24: 3 | C24: 720 | D24: 1186 | E24: =A24&"|"&B24 -> 3|3
A25: 3 | B25: 4 | C25: 848 | D25: 2027 | E25: =A25&"|"&B25 -> 3|4
A26: 3 | B26: 5 | C26: 600 | D26: 2027 | E26: =A26&"|"&B26 -> 3|5
A27: 3 | B27: 6 | C27: 707 | E27: =A27&"|"&B27 -> 3|6
A28: 3 | B28: 7 | C28: 909 | E28: =A28&"|"&B28 -> 3|7
A29: 3 | B29: 8 | C29: 858 | E29: =A29&"|"&B29 -> 3|8
A30: 3 | B30: 9 | C30: 645 | E30: =A30&"|"&B30 -> 3|9
A31: 3 | B31: 10 | C31: 605 | E31: =A31&"|"&B31 -> 3|10
A32: 4 | B32: 1 | C32: 1333 | D32: 1396 | E32: =A32&"|"&B32 -> 4|1
A33: 4 | B33: 2 | C33: 1471 | D33: 1501 | E33: =A33&"|"&B33 -> 4|2
A34: 4 | B34: 3 | C34: 1341 | D34: 1546 | E34: =A34&"|"&B34 -> 4|3
A35: 4 | B35: 4 | C35: 1200 | D35: 1411 | E35: =A35&"|"&B35 -> 4|4
A36: 4 | B36: 5 | C36: 1169 | D36: 1906 | E36: =A36&"|"&B36 -> 4|5
A37: 4 | B37: 6 | C37: 946 | D37: 1832 | E37: =A37&"|"&B37 -> 4|6
A38: 4 | B38: 7 | C38: 763 | E38: =A38&"|"&B38 -> 4|7
A39: 4 | B39: 8 | C39: 390 | E39: =A39&"|"&B39 -> 4|8
A40: 4 | B40: 9 | C40: 345 | E40: =A40&"|"&B40 -> 4|9
A41: 4 | B41: 10 | C41: 165 | E41: =A41&"|"&B41 -> 4|10
A42: 5 | B42: 1 | C42: 864 | D42: 812 | E42: =A42&"|"&B42 -> 5|1
A43: 5 | B43: 2 | C43: 421 | D43: 497 | E43: =A43&"|"&B43 -> 5|2
A44: 5 | B44: 3 | C44: 856 | D44: 797 | E44: =A44&"|"&B44 -> 5|3
A45: 5 | B45: 4 | C45: 1164 | D45: 1171 | E45: =A45&"|"&B45 -> 5|4
...

Sheet Factory_Stations
A1: Scenario | B1: Station | C1: Key | D1: Factory run time (s) | E1: Factory busy (s) | F1: Factory util. (%)
A2: 1 | B2: ws-03_S1toS4 | C2: =A2&"|"&B2 -> 1|ws-03_S1toS4 | D2: 2416 | E2: 1988 | F2: 82.284768
A3: 1 | B3: ws-04_S5S7 | C3: =A3&"|"&B3 -> 1|ws-04_S5S7 | D3: 2416 | E3: 756 | F3: 31.291391
A4: 1 | B4: ws-05_S6S8 | C4: =A4&"|"&B4 -> 1|ws-05_S6S8 | D4: 2416 | E4: 1290 | F4: 53.39404
A5: 2 | B5: ws-01_S1toS8 | C5: =A5&"|"&B5 -> 2|ws-01_S1toS8 | D5: 2416 | E5: 1906 | F5: 78.890728
A6: 2 | B6: ws-02_S1toS8 | C6: =A6&"|"&B6 -> 2|ws-02_S1toS8 | D6: 2416 | E6: 2221 | F6: 91.928808
A7: 2 | B7: ws-03_S1toS8 | C7: =A7&"|"&B7 -> 2|ws-03_S1toS8 | D7: 2416 | E7: 2248 | F7: 93.046358
A8: 2 | B8: ws-04_S1toS8 | C8: =A8&"|"&B8 -> 2|ws-04_S1toS8 | D8: 2416 | E8: 2371 | F8: 98.137417
A9: 3 | B9: ws-01_S1S2 | C9: =A9&"|"&B9 -> 3|ws-01_S1S2 | D9: 2387 | E9: 1171 | F9: 49.057394
A10: 3 | B10: ws-02_S3S4 | C10: =A10&"|"&B10 -> 3|ws-02_S3S4 | D10: 2387 | E10: 1875 | F10: 78.550482
A11: 3 | B11: ws-03_S5 | C11: =A11&"|"&B11 -> 3|ws-03_S5 | D11: 2387 | E11: 1173 | F11: 49.141181
A12: 3 | B12: ws-04_S7 | C12: =A12&"|"&B12 -> 3|ws-04_S7 | D12: 2387 | E12: 1379 | F12: 57.771261
A13: 3 | B13: ws-05_S6S8 | C13: =A13&"|"&B13 -> 3|ws-05_S6S8 | D13: 2387 | E13: 1600 | F13: 67.029744
... A28: 6 | B28: ws-05_S6S8 | C28: =A28&"|"&B28 -> 6|ws-05_S6S8 | D28: 2401 | E28: 1604 | F28: 66.805498

Sheet Factory_Components
A1: Scenario | B1: Part | C1: Code (doc) | D1: Group | E1: Description | F1: # per car | G1: Factory # POs | H1: Factory count | I1: Key
A2: 1 | B2: a | C2: BOSP | D2: BOSP | E2: Body + Spoiler | F2: 1+1 | G2: 8 | H2: 16 | I2: =A2&"|"&B2&"|"&D2 -> 1|a|BOSP
A3: 1 | B3: a | C3: RT | D3: RT | E3: Rear Tires | F3: 2 | G3: 10 | H3: 20 | I3: =A3&"|"&B3&"|"&D3 -> 1|a|RT
A4: 1 | B4: a | C4: FT | D4: FT | E4: Front Tires | F4: 2 | G4: 4 | H4: 8 | I4: =A4&"|"&B4&"|"&D4 -> 1|a|FT
A5: 1 | B5: a | C5: BAT | D5: BAT | E5: Battery | F5: 1 | G5: 2 | H5: 2 | I5: =A5&"|"&B5&"|"&D5 -> 1|a|BAT
A6: 1 | B6: a | C6: CORE | D6: CHS | E6: Engine Core | F6: 1 | G6: 6 | H6: 6 | I6: =A6&"|"&B6&"|"&D6 -> 1|a|CHS
A7: 1 | B7: a | C7: BSA | D7: BSA | E7: Big Shock Absorbers | F7: 2 | G7: 8 | H7: 16 | I7: =A7&"|"&B7&"|"&D7 -> 1|a|BSA
A8: 1 | B8: a | C8: SSA | D8: SSA | E8: Small Shock Absorbers | F8: 2 | G8: 2 | H8: 4 | I8: =A8&"|"&B8&"|"&D8 -> 1|a|SSA
A9: 1 | B9: b | C9: RAX (RD) | D9: RAX_RD | E9: Rear axis | F9: 1 | G9: 6 | H9: 6 | I9: =A9&"|"&B9&"|"&D9 -> 1|b|RAX_RD
A10: 1 | B10: b | C10: CRE (TL) | D10: CRE | E10: Chassis, remaining systems, engine | F10: 1 | G10: 2 | H10: 2 | I10: =A10&"|"&B10&"|"&D10 -> 1|b|CRE
A11: 1 | B11: b | C11: CSEB-NABS (SA) | D11: CSEB-NABS | E11: Chassis, systems, engine, body | F11: 1 | G11: 2 | H11: 2 | I11: =A11&"|"&B11&"|"&D11 -> 1|b|CSEB-NABS
A12: 2 | B12: a | C12: BOSP | D12: BOSP | E12: Body + Spoiler | F12: 1+1 | G12: 10 | H12: 20 | I12: =A12&"|"&B12&"|"&D12 -> 2|a|BOSP
A13: 2 | B13: a | C13: BAT | D13: BAT | E13: Battery | F13: 1 | G13: 10 | H13: 10 | I13: =A13&"|"&B13&"|"&D13 -> 2|a|BAT
... A25: 3 | B25: a | C25: SSA | D25: SSA | E25: Small Shock Absorbers | F25: 2 | G25: 9 | H25: 18 | I25: =A25&"|"&B25&"|"&D25 -> 3|a|SSA
A26: 3 | B26: a | C26: FAX | D26: FAX | E26: Front Axle | F26: 1 | G26: 10 | H26: 10 | I26: =A26&"|"&B26&"|"&D26 -> 3|a|FAX
A27: 3 | B27: a | C27: CHS | D27: CHS | E27: Chassis | F27: 1 | G27: 10 | H27: 10 | I27: =A27&"|"&B27&"|"&D27 -> 3|a|CHS
A28: 3 | B28: a | C28: BSA | D28: BSA | E28: Big Shock Absorbers | F28: 2 | G28: 5 | H28: 10 | I28: =A28&"|"&B28&"|"&D28 -> 3|a|BSA
A29: 3 | B29: b | C29: RAX (HD) | D29: RAX_HD | E29: Rear axis | F29: 1 | G29: 5 | H29: 5 | I29: =A29&"|"&B29&"|"&D29 -> 3|b|RAX_HD
A30: 4 | B30: a | C30: BOSP | D30: BOSP | E30: Body + Spoiler | F30: 1+1 | G30: 10 | H30: 20 | I30: =A30&"|"&B30&"|"&D30 -> 4|a|BOSP
A31: 4 | B31: a | C31: BAT | D31: BAT | E31: Battery | F31: 1 | G31: 10 | H31: 10 | I31: =A31&"|"&B31&"|"&D31 -> 4|a|BAT
A32: 4 | B32: a | C32: RT | D32: RT | E32: Rear Tires | F32: 2 | G32: 9 | H32: 18 | I32: =A32&"|"&B32&"|"&D32 -> 4|a|RT
A33: 4 | B33: a | C33: FT | D33: FT | E33: Front Tires | F33: 2 | G33: 8 | H33: 16 | I33: =A33&"|"&B33&"|"&D33 -> 4|a|FT
A34: 4 | B34: a | C34: SSA | D34: SSA | E34: Small Shock Absorbers | F34: 2 | G34: 7 | H34: 14 | I34: =A34&"|"&B34&"|"&D34 -> 4|a|SSA
A35: 4 | B35: a | C35: CHS | D35: CHS | E35: Chassis | F35: 1 | G35: 6 | H35: 6 | I35: =A35&"|"&B35&"|"&D35 -> 4|a|CHS
A36: 4 | B36: a | C36: BSA | D36: BSA | E36: Big Shock Absorbers | F36: 2 | G36: 6 | H36: 12 | I36: =A36&"|"&B36&"|"&D36 -> 4|a|BSA
A37: 4 | B37: a | C37: FAX | D37: FAX | E37: Front Axle | F37: 1 | G37: 7 | H37: 7 | I37: =A37&"|"&B37&"|"&D37 -> 4|a|FAX
A38: 4 | B38: b | C38: RAX (HD) | D38: RAX_HD | E38: Rear axis | F38: 1 | G38: 6 | H38: 6 | I38: =A38&"|"&B38&"|"&D38 -> 4|b|RAX_HD
... A62: 6 | B62: b | C62: CSEB-NABS (SA) | D62: CSEB-NABS | E62: Chassis, systems, engine, body | F62: 1 | G62: 3 | H62: 3 | I62: =A62&"|"&B62&"|"&D62 -> 6|b|CSEB-NABS

Sheet Calc_LeadTime
A1: Run | B1: Scenario | C1: PO | D1: Key | E1: Type | F1: Delivery (min) | G1: Exit (min) | H1: Lead time (min) | I1: Lead time (used) | J1: VT | K1: VT (used) | L1: NCT (workstations) | M1: NCT (used) | N1: Handling time (sim) | O1: Handling time (used) | P1: N outputs | Q1: N target | R1: Sim complete | S1: Factory handling time | T1: Factory handling time (used) | U1: Factory lead time | V1: Factory lead time (used) | W1: Factory complete | X1: Status | Y1: In average | Z1: Lead time Dev. | AA1: Lead time Dev. (used) | AB1: Used in (doc table)
A2: S1 | B2: 1 | C2: 1 | D2: =A2&"|"&C2 -> S1|1 | E2: =UPPER(MID(INDEX(raw_comp_PTA!$C$2:$C$81,MATCH(D2,raw_comp_PTA!$J$2:$J$81,0)),5,2)) -> RD | F2: =_xlfn.MINIFS(raw_outputtable!$J$2:$J$816,raw_outputtable!$A$2:$A$816,A2,raw_outputtable!$B$2:$B$816,C2) -> 0 | G2: =_xlfn.MAXIFS(raw_outputtable!$K$2:$K$816,raw_outputtable!$A$2:$A$816,A2,raw_outputtable!$B$2:$B$816,C2) -> 571.53333 | H2: =G2-F2 -> 571.53333 | I2: =IF($Y2=1,H2,"DNF") -> 571.53333 | J2: =INDEX(raw_comp_PTA!$H$2:$H$81,MATCH(D2,raw_comp_PTA!$J$2:$J$81,0)) -> 445.1 | K2: =IF($Y2=1,J2,"DNF") -> 445.1 | L2: =SUMIFS(raw_comp_PTA_stations!$E$2:$E$461,raw_comp_PTA_stations!$A$2:$A$461,A2,raw_comp_PTA_stations!$B$2:$B$461,C2,raw_comp_PTA_stations!$C$2:$C$461,"ws*") -> 90.23 | M2: =IF($Y2=1,L2,"DNF") -> 90.23 | N2: =INDEX(raw_comp_PTA!$G$2:$G$81,MATCH(D2,raw_comp_PTA!$J$2:$J$81,0)) -> 541.33 | O2: =IF($Y2=1,N2,"DNF") -> 541.33 | P2: =COUNTIFS(raw_outputtable!$A$2:$A$816,A2,raw_outputtable!$B$2:$B$816,C2) -> 8 | Q2: =INDEX(raw_casetable!$F$2:$F$81,MATCH(D2,raw_casetable!$G$2:$G$81,0)) -> 8 | R2: =IF(P2>=Q2,1,0) -> 1 | S2: =IFERROR(IF(INDEX(Factory_PO!$C$2:$C$61,MATCH(B2&"|"&C2,Factory_PO!$E$2:$E$61,0))="","",INDEX(Factory_PO!$C$2:$C$61,MATCH(B2&"|"&C2,Factory_PO!$E$2:$E$61,0))),"") -> 629 | T2: =IF($Y2=1,S2,"DNF") -> 629 | U2: =IFERROR(IF(INDEX(Factory_PO!$D$2:$D$61,MATCH(B2&"|"&C2,Factory_PO!$E$2:$E$61,0))="","",INDEX(Factory_PO!$D$2:$D$61,MATCH(B2&"|"&C2,Factory_PO!$E$2:$E$61,0))),"") -> 586 | V2: =IF($Y2=1,U2,"DNF") -> 586 | W2: =IF(U2="",0,1) -> 1 | X2: =IF(AND(R2=1,W2=1),"Complete",IF(AND(R2=0,W2=0),"DNF (sim + factory)",IF(R2=0,"DNF (sim)","DNF (factory)"))) -> Complete | Y2: =IF(X2="Complete",1,0) -> 1 | Z2: =IF(U2="","",(H2-U2)/U2) -> -0.024687145 | AA2: =IF($Y2=1,Z2,"DNF") -> -0.024687145 | AB2: Table 3.1
A3: S1 | B3: 1 | C3: 2 | D3: =A3&"|"&C3 -> S1|2 | E3: =UPPER(MID(INDEX(raw_comp_PTA!$C$2:$C$81,MATCH(D3,raw_comp_PTA!$J$2:$J$81,0)),5,2)) -> RD | F3: =_xlfn.MINIFS(raw_outputtable!$J$2:$J$816,raw_outputtable!$A$2:$A$816,A3,raw_outputtable!$B$2:$B$816,C3) -> 120 | G3: =_xlfn.MAXIFS(raw_outputtable!$K$2:$K$816,raw_outputtable!$A$2:$A$816,A3,raw_outputtable!$B$2:$B$816,C3) -> 753.06667 | H3: =G3-F3 -> 633.06667 | I3: =IF($Y3=1,H3,"DNF") -> 633.06667 | J3: =INDEX(raw_comp_PTA!$H$2:$H$81,MATCH(D3,raw_comp_PTA!$J$2:$J$81,0)) -> 445.1 | K3: =IF($Y3=1,J3,"DNF") -> 445.1 | L3: =SUMIFS(raw_comp_PTA_stations!$E$2:$E$461,raw_comp_PTA_stations!$A$2:$A$461,A3,raw_comp_PTA_stations!$B$2:$B$461,C3,raw_comp_PTA_stations!$C$2:$C$461,"ws*") -> 145.1 | M3: =IF($Y3=1,L3,"DNF") -> 145.1 | N3: =INDEX(raw_comp_PTA!$G$2:$G$81,MATCH(D3,raw_comp_PTA!$J$2:$J$81,0)) -> 601.14 | O3: =IF($Y3=1,N3,"DNF") -> 601.14 | P3: =COUNTIFS(raw_outputtable!$A$2:$A$816,A3,raw_outputtable!$B$2:$B$816,C3) -> 8 | Q3: =INDEX(raw_casetable!$F$2:$F$81,MATCH(D3,raw_casetable!$G$2:$G$81,0)) -> 8 | R3: =IF(P3>=Q3,1,0) -> 1 | S3: =IFERROR(IF(INDEX(Factory_PO!$C$2:$C$61,MATCH(B3&"|"&C3,Factory_PO!$E$2:$E$61,0))="","",INDEX(Factory_PO!$C$2:$C$61,MATCH(B3&"|"&C3,Factory_PO!$E$2:$E$61,0))),"") -> 482 | T3: =IF($Y3=1,S3,"DNF") -> 482 | U3: =IFERROR(IF(INDEX(Factory_PO!$D$2:$D$61,MATCH(B3&"|"&C3,Factory_PO!$E$2:$E$61,0))="","",INDEX(Factory_PO!$D$2:$D$61,MATCH(B3&"|"&C3,Factory_PO!$E$2:$E$61,0))),"") -> 721 | V3: =IF($Y3=1,U3,"DNF") -> 721 | W3: =IF(U3="",0,1) -> 1 | X3: =IF(AND(R3=1,W3=1),"Complete",IF(AND(R3=0,W3=0),"DNF (sim + factory)",IF(R3=0,"DNF (sim)","DNF (factory)"))) -> Complete | Y3: =IF(X3="Complete",1,0) -> 1 | Z3: =IF(U3="","",(H3-U3)/U3) -> -0.12196024 | AA3: =IF($Y3=1,Z3,"DNF") -> -0.12196024 | AB3: Table 3.1
A4: S1 | B4: 1 | C4: 3 | D4: =A4&"|"&C4 -> S1|3 | E4: =UPPER(MID(INDEX(raw_comp_PTA!$C$2:$C$81,MATCH(D4,raw_comp_PTA!$J$2:$J$81,0)),5,2)) -> RD | F4: =_xlfn.MINIFS(raw_outputtable!$J$2:$J$816,raw_outputtable!$A$2:$A$816,A4,raw_outputtable!$B$2:$B$816,C4) -> 240 | G4: =_xlfn.MAXIFS(raw_outputtable!$K$2:$K$816,raw_outputtable!$A$2:$A$816,A4,raw_outputtable!$B$2:$B$816,C4) -> 901.53333 | H4: =G4-F4 -> 661.53333 | I4: =IF($Y4=1,H4,"DNF") -> 661.53333 | J4: =INDEX(raw_comp_PTA!$H$2:$H$81,MATCH(D4,raw_comp_PTA!$J$2:$J$81,0)) -> 445.1 | K4: =IF($Y4=1,J4,"DNF") -> 445.1 | L4: =SUMIFS(raw_comp_PTA_stations!$E$2:$E$461,raw_comp_PTA_stations!$A$2:$A$461,A4,raw_comp_PTA_stations!$B$2:$B$461,C4,raw_comp_PTA_stations!$C$2:$C$461,"ws*") -> 178.33 | M4: =IF($Y4=1,L4,"DNF") -> 178.33 | N4: =INDEX(raw_comp_PTA!$G$2:$G$81,MATCH(D4,raw_comp_PTA!$J$2:$J$81,0)) -> 629.6 | O4: =IF($Y4=1,N4,"DNF") -> 629.6 | P4: =COUNTIFS(raw_outputtable!$A$2:$A$816,A4,raw_outputtable!$B$2:$B$816,C4) -> 8 | Q4: =INDEX(raw_casetable!$F$2:$F$81,MATCH(D4,raw_casetable!$G$2:$G$81,0)) -> 8 | R4: =IF(P4>=Q4,1,0) -> 1 | S4: =IFERROR(IF(INDEX(Factory_PO!$C$2:$C$61,MATCH(B4&"|"&C4,Factory_PO!$E$2:$E$61,0))="","",INDEX(Factory_PO!$C$2:$C$61,MATCH(B4&"|"&C4,Factory_PO!$E$2:$E$61,0))),"") -> 360 | T4: =IF($Y4=1,S4,"DNF") -> 360 | U4: =IFERROR(IF(INDEX(Factory_PO!$D$2:$D$61,MATCH(B4&"|"&C4,Factory_PO!$E$2:$E$61,0))="","",INDEX(Factory_PO!$D$2:$D$61,MATCH(B4&"|"&C4,Factory_PO!$E$2:$E$61,0))),"") -> 721 | V4: =IF($Y4=1,U4,"DNF") -> 721 | W4: =IF(U4="",0,1) -> 1 | X4: =IF(AND(R4=1,W4=1),"Complete",IF(AND(R4=0,W4=0),"DNF (sim + factory)",IF(R4=0,"DNF (sim)","DNF (factory)"))) -> Complete | Y4: =IF(X4="Complete",1,0) -> 1 | Z4: =IF(U4="","",(H4-U4)/U4) -> -0.08247804 | AA4: =IF($Y4=1,Z4,"DNF") -> -0.08247804 | AB4: Table 3.1
A5: S1 | B5: 1 | C5: 4 | D5: =A5&"|"&C5 -> S1|4 | E5: =UPPER(MID(INDEX(raw_comp_PTA!$C$2:$C$81,MATCH(D5,raw_comp_PTA!$J$2:$J$81,0)),5,2)) -> TL | F5: =_xlfn.MINIFS(raw_outputtable!$J$2:$J$816,raw_outputtable!$A$2:$A$816,A5,raw_outputtable!$B$2:$B$816,C5) -> 360 | G5: =_xlfn.MAXIFS(raw_outputtable!$K$2:$K$816,raw_outputtable!$A$2:$A$816,A5,raw_outputtable!$B$2:$B$816,C5) -> 961.53333 | H5: =G5-F5 -> 601.53333 | I5: =IF($Y5=1,H5,"DNF") -> 601.53333 | J5: =INDEX(raw_comp_PTA!$H$2:$H$81,MATCH(D5,raw_comp_PTA!$J$2:$J$81,0)) -> 374.1 | K5: =IF($Y5=1,J5,"DNF") -> 374.1 | L5: =SUMIFS(raw_comp_PTA_stations!$E$2:$E$461,raw_comp_PTA_stations!$A$2:$A$461,A5,raw_comp_PTA_stations!$B$2:$B$461,C5,raw_comp_PTA_stations!$C$2:$C$461,"ws*") -> 189.5 | M5: =IF($Y5=1,L5,"DNF") -> 189.5 | N5: =INDEX(raw_comp_PTA!$G$2:$G$81,MATCH(D5,raw_comp_PTA!$J$2:$J$81,0)) -> 566.2 | O5: =IF($Y5=1,N5,"DNF") -> 566.2 | P5: =COUNTIFS(raw_outputtable!$A$2:$A$816,A5,raw_outputtable!$B$2:$B$816,C5) -> 8 | Q5: =INDEX(raw_casetable!$F$2:$F$81,MATCH(D5,raw_casetable!$G$2:$G$81,0)) -> 8 | R5: =IF(P5>=Q5,1,0) -> 1 | S5: =IFERROR(IF(INDEX(Factory_PO!$C$2:$C$61,MATCH(B5&"|"&C5,Factory_PO!$E$2:$E$61,0))="","",INDEX(Factory_PO!$C$2:$C$61,MATCH(B5&"|"&C5,Factory_PO!$E$2:$E$61,0))),"") -> 402 | T5: =IF($Y5=1,S5,"DNF") -> 402 | U5: =IFERROR(IF(INDEX(Factory_PO!$D$2:$D$61,MATCH(B5&"|"&C5,Factory_PO!$E$2:$E$61,0))="","",INDEX(Factory_PO!$D$2:$D$61,MATCH(B5&"|"&C5,Factory_PO!$E$2:$E$61,0))),"") -> 530 | V5: =IF($Y5=1,U5,"DNF") -> 530 | W5: =IF(U5="",0,1) -> 1 | X5: =IF(AND(R5=1,W5=1),"Complete",IF(AND(R5=0,W5=0),"DNF (sim + factory)",IF(R5=0,"DNF (sim)","DNF (factory)"))) -> Complete | Y5: =IF(X5="Complete",1,0) -> 1 | Z5: =IF(U5="","",(H5-U5)/U5) -> 0.13496855 | AA5: =IF($Y5=1,Z5,"DNF") -> 0.13496855 | AB5: Table 3.1
A6: S1 | B6: 1 | C6: 5 | D6: =A6&"|"&C6 -> S1|5 | E6: =UPPER(MID(INDEX(raw_comp_PTA!$C$2:$C$81,MATCH(D6,raw_comp_PTA!$J$2:$J$81,0)),5,2)) -> SA | F6: =_xlfn.MINIFS(raw_outputtable!$J$2:$J$816,raw_outputtable!$A$2:$A$816,A6,raw_outputtable!$B$2:$B$816,C6) -> 540 | G6: =_xlfn.MAXIFS(raw_outputtable!$K$2:$K$816,raw_outputtable!$A$2:$A$816,A6,raw_outputtable!$B$2:$B$816,C6) -> 1444.9333 | H6: =G6-F6 -> 904.93333 | I6: =IF($Y6=1,H6,"DNF") -> 904.93333 | J6: =INDEX(raw_comp_PTA!$H$2:$H$81,MATCH(D6,raw_comp_PTA!$J$2:$J$81,0)) -> 444.1 | K6: =IF($Y6=1,J6,"DNF") -> 444.1 | L6: =SUMIFS(raw_comp_PTA_stations!$E$2:$E$461,raw_comp_PTA_stations!$A$2:$A$461,A6,raw_comp_PTA_stations!$B$2:$B$461,C6,raw_comp_PTA_stations!$C$2:$C$461,"ws*") -> 418.84 | M6: =IF($Y6=1,L6,"DNF") -> 418.84 | N6: =INDEX(raw_comp_PTA!$G$2:$G$81,MATCH(D6,raw_comp_PTA!$J$2:$J$81,0)) -> 871.46 | O6: =IF($Y6=1,N6,"DNF") -> 871.46 | P6: =COUNTIFS(raw_outputtable!$A$2:$A$816,A6,raw_outputtable!$B$2:$B$816,C6) -> 9 | Q6: =INDEX(raw_casetable!$F$2:$F$81,MATCH(D6,raw_casetable!$G$2:$G$81,0)) -> 9 | R6: =IF(P6>=Q6,1,0) -> 1 | S6: =IFERROR(IF(INDEX(Factory_PO!$C$2:$C$61,MATCH(B6&"|"&C6,Factory_PO!$E$2:$E$61,0))="","",INDEX(Factory_PO!$C$2:$C$61,MATCH(B6&"|"&C6,Factory_PO!$E$2:$E$61,0))),"") -> 555 | T6: =IF($Y6=1,S6,"DNF") -> 555 | U6: =IFERROR(IF(INDEX(Factory_PO!$D$2:$D$61,MATCH(B6&"|"&C6,Factory_PO!$E$2:$E$61,0))="","",INDEX(Factory_PO!$D$2:$D$61,MATCH(B6&"|"&C6,Factory_PO!$E$2:$E$61,0))),"") -> 976 | V6: =IF($Y6=1,U6,"DNF") -> 976 | W6: =IF(U6="",0,1) -> 1 | X6: =IF(AND(R6=1,W6=1),"Complete",IF(AND(R6=0,W6=0),"DNF (sim + factory)",IF(R6=0,"DNF (sim)","DNF (factory)"))) -> Complete | Y6: =IF(X6="Complete",1,0) -> 1 | Z6: =IF(U6="","",(H6-U6)/U6) -> -0.072814208 | AA6: =IF($Y6=1,Z6,"DNF") -> -0.072814208 | AB6: Table 3.1
A7: S1 | B7: 1 | C7: 6 | D7: =A7&"|"&C7 -> S1|6 | E7: =UPPER(MID(INDEX(raw_comp_PTA!$C$2:$C$81,MATCH(D7,raw_comp_PTA!$J$2:$J$81,0)),5,2)) -> RD | F7: =_xlfn.MINIFS(raw_outputtable!$J$2:$J$816,raw_outputtable!$A$2:$A$816,A7,raw_outputtable!$B$2:$B$816,C7) -> 600 | G7: =_xlfn.MAXIFS(raw_outputtable!$K$2:$K$816,raw_outputtable!$A$2:$A$816,A7,raw_outputtable!$B$2:$B$816,C7) -> 1621.5333 | H7: =G7-F7 -> 1021.5333 | I7: =IF($Y7=1,H7,"DNF") -> 1021.5333 | J7: =INDEX(raw_comp_PTA!$H$2:$H$81,MATCH(D7,raw_comp_PTA!$J$2:$J$81,0)) -> 445.1 | K7: =IF($Y7=1,J7,"DNF") -> 445.1 | L7: =SUMIFS(raw_comp_PTA_stations!$E$2:$E$461,raw_comp_PTA_stations!$A$2:$A$461,A7,raw_comp_PTA_stations!$B$2:$B$461,C7,raw_comp_PTA_stations!$C$2:$C$461,"ws*") -> 533.9 | M7: =IF($Y7=1,L7,"DNF") -> 533.9 | N7: =INDEX(raw_comp_PTA!$G$2:$G$81,MATCH(D7,raw_comp_PTA!$J$2:$J$81,0)) -> 986.53 | O7: =IF($Y7=1,N7,"DNF") -> 986.53 | P7: =COUNTIFS(raw_outputtable!$A$2:$A$816,A7,raw_outputtable!$B$2:$B$816,C7) -> 8 | Q7: =INDEX(raw_casetable!$F$2:$F$81,MATCH(D7,raw_casetable!$G$2:$G$81,0)) -> 8 | R7: =IF(P7>=Q7,1,0) -> 1 | S7: =IFERROR(IF(INDEX(Factory_PO!$C$2:$C$61,MATCH(B7&"|"&C7,Factory_PO!$E$2:$E$61,0))="","",INDEX(Factory_PO!$C$2:$C$61,MATCH(B7&"|"&C7,Factory_PO!$E$2:$E$61,0))),"") -> 480 | T7: =IF($Y7=1,S7,"DNF") -> 480 | U7: =IFERROR(IF(INDEX(Factory_PO!$D$2:$D$61,MATCH(B7&"|"&C7,Factory_PO!$E$2:$E$61,0))="","",INDEX(Factory_PO!$D$2:$D$61,MATCH(B7&"|"&C7,Factory_PO!$E$2:$E$61,0))),"") -> 1231 | V7: =IF($Y7=1,U7,"DNF") -> 1231 | W7: =IF(U7="",0,1) -> 1 | X7: =IF(AND(R7=1,W7=1),"Complete",IF(AND(R7=0,W7=0),"DNF (sim + factory)",IF(R7=0,"DNF (sim)","DNF (factory)"))) -> Complete | Y7: =IF(X7="Complete",1,0) -> 1 | Z7: =IF(U7="","",(H7-U7)/U7) -> -0.17015976 | AA7: =IF($Y7=1,Z7,"DNF") -> -0.17015976 | AB7: Table 3.1
